<?xml version="1.0" encoding="UTF-8" ?>
<rss version="2.0" xmlns:atom="http://www.w3.org/2005/Atom" xmlns:dc="http://purl.org/dc/elements/1.1/">
  <channel>
    <title>Upgrade v8 -&gt; v10: Can&#39;t login to redash anymore</title>
    <link>https://discuss.redash.io/t/upgrade-v8-v10-cant-login-to-redash-anymore/9562</link>
    <description>Hi there!

After my [initial problem](http://discuss.redash.io/t/i-cant-use-pandas-json-normalize-within-a-python-query/9560)  I tried to upgrade redash from v8 to v10 and followed [this instruction](https://github.com/getredash/redash/releases/tag/v10.0.0) very carefully. But since that I can&#39;t login to redash anymore ... If I open localhost:8888/login I get a **&quot;500 Internal Server Error&quot;** with the following response:

```
server_1            | [2021-11-27 11:55:15,819][PID:12][ERROR][redash.app] Exception on /login [GET]
server_1            | Traceback (most recent call last):
server_1            |   File &quot;/usr/local/lib/python3.7/site-packages/sqlalchemy/engine/base.py&quot;, line 1249, in _execute_context
server_1            |     cursor, statement, parameters, context
server_1            |   File &quot;/usr/local/lib/python3.7/site-packages/sqlalchemy/engine/default.py&quot;, line 580, in do_execute
server_1            |     cursor.execute(statement, parameters)
server_1            | psycopg2.errors.UndefinedTable: relation &quot;organizations&quot; does not exist
server_1            | LINE 2: FROM organizations
server_1            |              ^
server_1            |
server_1            |
server_1            | The above exception was the direct cause of the following exception:
server_1            |
server_1            | Traceback (most recent call last):
server_1            |   File &quot;/usr/local/lib/python3.7/site-packages/flask/app.py&quot;, line 2446, in wsgi_app
server_1            |     response = self.full_dispatch_request()
server_1            |   File &quot;/usr/local/lib/python3.7/site-packages/flask/app.py&quot;, line 1951, in full_dispatch_request
server_1            |     rv = self.handle_user_exception(e)
server_1            |   File &quot;/usr/local/lib/python3.7/site-packages/flask_restful/__init__.py&quot;, line 269, in error_router
server_1            |     return original_handler(e)
server_1            |   File &quot;/usr/local/lib/python3.7/site-packages/flask/app.py&quot;, line 1820, in handle_user_exception
server_1            |     reraise(exc_type, exc_value, tb)
server_1            |   File &quot;/usr/local/lib/python3.7/site-packages/flask/_compat.py&quot;, line 39, in reraise
server_1            |     raise value
server_1            |   File &quot;/usr/local/lib/python3.7/site-packages/flask/app.py&quot;, line 1949, in full_dispatch_request
server_1            |     rv = self.dispatch_request()
server_1            |   File &quot;/usr/local/lib/python3.7/site-packages/flask/app.py&quot;, line 1935, in dispatch_request
server_1            |     return self.view_functions[rule.endpoint](**req.view_args)
server_1            |   File &quot;/usr/local/lib/python3.7/site-packages/flask_limiter/extension.py&quot;, line 442, in __inner
server_1            |     return obj(*a, **k)
server_1            |   File &quot;/app/redash/handlers/authentication.py&quot;, line 190, in login
server_1            |     if current_org == None and not settings.MULTI_ORG:
server_1            |   File &quot;/usr/local/lib/python3.7/site-packages/werkzeug/local.py&quot;, line 370, in &lt;lambda&gt;
server_1            |     __eq__ = lambda x, o: x._get_current_object() == o
server_1            |   File &quot;/usr/local/lib/python3.7/site-packages/werkzeug/local.py&quot;, line 307, in _get_current_object
server_1            |     return self.__local()
server_1            |   File &quot;/app/redash/authentication/org_resolving.py&quot;, line 18, in _get_current_org
server_1            |     g.org = Organization.get_by_slug(slug)
server_1            |   File &quot;/app/redash/models/organizations.py&quot;, line 31, in get_by_slug
server_1            |     return cls.query.filter(cls.slug == slug).first()
server_1            |   File &quot;/usr/local/lib/python3.7/site-packages/sqlalchemy/orm/query.py&quot;, line 3240, in first
server_1            |     ret = list(self[0:1])
server_1            |   File &quot;/usr/local/lib/python3.7/site-packages/sqlalchemy/orm/query.py&quot;, line 3018, in __getitem__server_1            |     return list(res)
server_1            |   File &quot;/usr/local/lib/python3.7/site-packages/sqlalchemy/orm/query.py&quot;, line 3342, in __iter__
server_1            |     return self._execute_and_instances(context)
server_1            |   File &quot;/usr/local/lib/python3.7/site-packages/sqlalchemy/orm/query.py&quot;, line 3367, in _execute_and_instances
server_1            |     result = conn.execute(querycontext.statement, self._params)
server_1            |   File &quot;/usr/local/lib/python3.7/site-packages/sqlalchemy/engine/base.py&quot;, line 988, in execute
server_1            |     return meth(self, multiparams, params)
server_1            |   File &quot;/usr/local/lib/python3.7/site-packages/sqlalchemy/sql/elements.py&quot;, line 287, in _execute_on_connection
server_1            |     return connection._execute_clauseelement(self, multiparams, params)
server_1            |   File &quot;/usr/local/lib/python3.7/site-packages/sqlalchemy/engine/base.py&quot;, line 1107, in _execute_clauseelement
server_1            |     distilled_params,
server_1            |   File &quot;/usr/local/lib/python3.7/site-packages/sqlalchemy/engine/base.py&quot;, line 1253, in _execute_context
server_1            |     e, statement, parameters, cursor, context
server_1            |   File &quot;/usr/local/lib/python3.7/site-packages/sqlalchemy/engine/base.py&quot;, line 1473, in _handle_dbapi_exception
server_1            |     util.raise_from_cause(sqlalchemy_exception, exc_info)
server_1            |   File &quot;/usr/local/lib/python3.7/site-packages/sqlalchemy/util/compat.py&quot;, line 398, in raise_from_cause
server_1            |     reraise(type(exception), exception, tb=exc_tb, cause=cause)
server_1            |   File &quot;/usr/local/lib/python3.7/site-packages/sqlalchemy/util/compat.py&quot;, line 152, in reraise
server_1            |     raise value.with_traceback(tb)
server_1            |   File &quot;/usr/local/lib/python3.7/site-packages/sqlalchemy/engine/base.py&quot;, line 1249, in _execute_context
server_1            |     cursor, statement, parameters, context
server_1            |   File &quot;/usr/local/lib/python3.7/site-packages/sqlalchemy/engine/default.py&quot;, line 580, in do_execute
server_1            |     cursor.execute(statement, parameters)
server_1            | sqlalchemy.exc.ProgrammingError: (psycopg2.errors.UndefinedTable) relation &quot;organizations&quot; does not exist
server_1            | LINE 2: FROM organizations
server_1            |              ^
server_1            |
server_1            | [SQL: SELECT organizations.updated_at AS organizations_updated_at, organizations.created_at AS organizations_created_at, organizations.id AS organizations_id, organizations.name AS organizations_name, organizations.slug AS organizations_slug, organizations.settings AS organizations_settings
server_1            | FROM organizations
server_1            | WHERE organizations.slug = %(slug_1)s
server_1            |  LIMIT %(param_1)s]
server_1            | [parameters: {&#39;slug_1&#39;: &#39;default&#39;, &#39;param_1&#39;: 1}]
server_1            | (Background on this error at: http://sqlalche.me/e/f405)
server_1            | [2021-11-27 11:55:15,824][PID:12][INFO][metrics] method=GET path=/login endpoint=redash_login status=500 content_type=text/html content_length=290 duration=99.49 query_count=0 query_duration=0.00
server_1            | [2021-11-27 11:55:15,826][PID:12][INFO][metrics] method=GET path=/login endpoint=redash_login status=500 content_type=? content_length=-1 duration=101.18 query_count=0 query_duration=0.00
nginx_1             | 172.18.0.1 - - [27/Nov/2021:11:55:15 +0000] &quot;GET /login?next=http%3A%2F%2Flocalhost%3A8888%2Ffavicon.ico HTTP/1.1&quot; 500 290 &quot;http://localhost:8888/login&quot; &quot;Mozilla/5.0 (Windows NT 10.0; Win64; x64) AppleWebKit/537.36 (KHTML, like Gecko) Chrome/96.0.4664.45 Safari/537.36&quot; &quot;-&quot;
```

This is my docker-compose.yml:


```
version: &quot;2&quot;
x-redash-service: &amp;redash-service
  image: redash/redash:10.0.0.b50363
  depends_on:
    - postgres
    - redis
  env_file: G:\redash\.env
  restart: always
services:
  server:
    &lt;&lt;: *redash-service
    command: server
    ports:
      - &quot;5000:5000&quot;
    environment:
      REDASH_WEB_WORKERS: 4
  scheduler:
    &lt;&lt;: *redash-service
    command: scheduler
  scheduled_worker:
    &lt;&lt;: *redash-service
    command: worker
    environment:
      QUEUES: &quot;scheduled_queries,schemas&quot;
      WORKERS_COUNT: 1
  adhoc_worker:
    &lt;&lt;: *redash-service
    command: worker
    environment:
      QUEUES: &quot;queries&quot;
      WORKERS_COUNT: 2
  worker:
    &lt;&lt;: *redash-service
    command: worker
    environment:
      QUEUES: &quot;periodic emails default&quot;
      WORKERS_COUNT: 1      
  redis:
    image: redis:5.0-alpine
    restart: always
  postgres:
    image: postgres:9.6-alpine
    env_file: G:\redash\.env
    volumes:
      - /opt/redash/postgres-data:/var/lib/postgresql/data
    restart: always
  nginx:
    image: redash/nginx:latest
    ports:
      - &quot;8888:80&quot;
    depends_on:
      - server
    links:
      - server:redash
    restart: always
```

What am I doing wrong? I really appreciate your help! Thanks</description>
    
    <lastBuildDate>Tue, 30 Nov 2021 07:08:24 +0000</lastBuildDate>
    <category>Support</category>
    <atom:link href="https://discuss.redash.io/t/upgrade-v8-v10-cant-login-to-redash-anymore/9562.rss" rel="self" type="application/rss+xml" />
      <item>
        <title>Upgrade v8 -&gt; v10: Can&#39;t login to redash anymore</title>
        <dc:creator><![CDATA[Schmabudi]]></dc:creator>
        <description><![CDATA[
            <p>Appreciated, thank you very much. I will try it out!</p>
          <p><a href="https://discuss.redash.io/t/upgrade-v8-v10-cant-login-to-redash-anymore/9562/8">Read full topic</a></p>
        ]]></description>
        <link>https://discuss.redash.io/t/upgrade-v8-v10-cant-login-to-redash-anymore/9562/8</link>
        <pubDate>Tue, 30 Nov 2021 07:08:24 +0000</pubDate>
        <guid isPermaLink="false">discuss.redash.io-post-9562-8</guid>
        <source url="https://discuss.redash.io/t/upgrade-v8-v10-cant-login-to-redash-anymore/9562.rss">Upgrade v8 -&gt; v10: Can&#39;t login to redash anymore</source>
      </item>
      <item>
        <title>Upgrade v8 -&gt; v10: Can&#39;t login to redash anymore</title>
        <dc:creator><![CDATA[jesse]]></dc:creator>
        <description><![CDATA[
            <aside class="quote no-group" data-username="Schmabudi" data-post="6" data-topic="9562">
<div class="title">
<div class="quote-controls"></div>
<img alt="" width="20" height="20" src="https://avatars.discourse-cdn.com/v4/letter/s/41988e/40.png" class="avatar"> Schmabudi:</div>
<blockquote>
<p>Yes, I’m running redash local from my computer, just to get in touch with the mechanics.</p>
</blockquote>
</aside>
<p>I think for this you should follow the well-defined process for running Redash locally: <a href="https://redash.io/help/open-source/dev-guide/docker">https://redash.io/help/open-source/dev-guide/docker</a></p>
          <p><a href="https://discuss.redash.io/t/upgrade-v8-v10-cant-login-to-redash-anymore/9562/7">Read full topic</a></p>
        ]]></description>
        <link>https://discuss.redash.io/t/upgrade-v8-v10-cant-login-to-redash-anymore/9562/7</link>
        <pubDate>Mon, 29 Nov 2021 21:27:15 +0000</pubDate>
        <guid isPermaLink="false">discuss.redash.io-post-9562-7</guid>
        <source url="https://discuss.redash.io/t/upgrade-v8-v10-cant-login-to-redash-anymore/9562.rss">Upgrade v8 -&gt; v10: Can&#39;t login to redash anymore</source>
      </item>
      <item>
        <title>Upgrade v8 -&gt; v10: Can&#39;t login to redash anymore</title>
        <dc:creator><![CDATA[Schmabudi]]></dc:creator>
        <description><![CDATA[
            <p>Thanks for asking: Yes, I’m running redash local from my computer, just to get in touch with the mechanics. For that I used this docker-compose.yml <a href="https://raw.githubusercontent.com/getredash/setup/master/data/docker-compose.yml" rel="noopener nofollow ugc">here</a> and I modified it. But you’re absolutely right: The location of volume does not match with my local computer. Do you have any suggestions to modify the docker-compose.yml further to make it suitable for a local running?</p>
          <p><a href="https://discuss.redash.io/t/upgrade-v8-v10-cant-login-to-redash-anymore/9562/6">Read full topic</a></p>
        ]]></description>
        <link>https://discuss.redash.io/t/upgrade-v8-v10-cant-login-to-redash-anymore/9562/6</link>
        <pubDate>Mon, 29 Nov 2021 19:45:23 +0000</pubDate>
        <guid isPermaLink="false">discuss.redash.io-post-9562-6</guid>
        <source url="https://discuss.redash.io/t/upgrade-v8-v10-cant-login-to-redash-anymore/9562.rss">Upgrade v8 -&gt; v10: Can&#39;t login to redash anymore</source>
      </item>
      <item>
        <title>Upgrade v8 -&gt; v10: Can&#39;t login to redash anymore</title>
        <dc:creator><![CDATA[jesse]]></dc:creator>
        <description><![CDATA[
            <p>What you’re describing is not normal behavior. It sounds like you configured Redash to save its database to a temporary folder that is deleted whenever you restart. This is not suitable for production use.</p>
<p>How exactly did you install Redash? Your compose file appears to be borrowed from the cloud AMI. But you’re running it on your local computer? Notice that the postgres service defines a mapped volume where all the data will be stored. Does this map to a real location on your local computer?</p>
          <p><a href="https://discuss.redash.io/t/upgrade-v8-v10-cant-login-to-redash-anymore/9562/5">Read full topic</a></p>
        ]]></description>
        <link>https://discuss.redash.io/t/upgrade-v8-v10-cant-login-to-redash-anymore/9562/5</link>
        <pubDate>Sun, 28 Nov 2021 18:44:52 +0000</pubDate>
        <guid isPermaLink="false">discuss.redash.io-post-9562-5</guid>
        <source url="https://discuss.redash.io/t/upgrade-v8-v10-cant-login-to-redash-anymore/9562.rss">Upgrade v8 -&gt; v10: Can&#39;t login to redash anymore</source>
      </item>
      <item>
        <title>Upgrade v8 -&gt; v10: Can&#39;t login to redash anymore</title>
        <dc:creator><![CDATA[Schmabudi]]></dc:creator>
        <description><![CDATA[
            <p>Thank you very much jesse for your answer. Your suggestion helped, I needed to initialise my database. As I recall I couldnt back-up my database correctly (?) but I didnt run <em>docker-compose down</em> during the upgrade (I didnt run the development setup either). But I’m glad that it works now.</p>
<p>There is but one thing: If I stop my docker container ( docker-compose stop ) und restart my computer, I need to initialise <strong>again</strong> my database in order to access redash(?). This comes only If I restart/shutdown my computer. If I stop the containter and I restart the containter again, I can access redash by my credentials. Do I need to save my intialised database somehow before shuting down my pc?</p>
          <p><a href="https://discuss.redash.io/t/upgrade-v8-v10-cant-login-to-redash-anymore/9562/4">Read full topic</a></p>
        ]]></description>
        <link>https://discuss.redash.io/t/upgrade-v8-v10-cant-login-to-redash-anymore/9562/4</link>
        <pubDate>Sun, 28 Nov 2021 10:15:21 +0000</pubDate>
        <guid isPermaLink="false">discuss.redash.io-post-9562-4</guid>
        <source url="https://discuss.redash.io/t/upgrade-v8-v10-cant-login-to-redash-anymore/9562.rss">Upgrade v8 -&gt; v10: Can&#39;t login to redash anymore</source>
      </item>
      <item>
        <title>Upgrade v8 -&gt; v10: Can&#39;t login to redash anymore</title>
        <dc:creator><![CDATA[jesse]]></dc:creator>
        <description><![CDATA[
            <p>Thanks for your detailed description.</p>
<p>That error  <em>usually</em> means that your database hasn’t been initialised. You can initialise it with <code>docker-compose run --rm server create_db</code>. That command is part of the instructions for a fresh installation. It’s weird that it seems necessary during an <em>upgrade</em>.</p>
<p>Are you running the development setup? Did you happen to run <code>docker-compose down</code> during the upgrade? Did you back-up your database before you began?</p>
          <p><a href="https://discuss.redash.io/t/upgrade-v8-v10-cant-login-to-redash-anymore/9562/3">Read full topic</a></p>
        ]]></description>
        <link>https://discuss.redash.io/t/upgrade-v8-v10-cant-login-to-redash-anymore/9562/3</link>
        <pubDate>Sat, 27 Nov 2021 14:20:56 +0000</pubDate>
        <guid isPermaLink="false">discuss.redash.io-post-9562-3</guid>
        <source url="https://discuss.redash.io/t/upgrade-v8-v10-cant-login-to-redash-anymore/9562.rss">Upgrade v8 -&gt; v10: Can&#39;t login to redash anymore</source>
      </item>
      <item>
        <title>Upgrade v8 -&gt; v10: Can&#39;t login to redash anymore</title>
        <dc:creator><![CDATA[Schmabudi]]></dc:creator>
        <description><![CDATA[
            <p>I’ll try to provide more informations. Feel free to ask for more information if I missing something out:</p>
<p><strong>Browser/OS: Google Chrome/ Windows 10</strong></p>
<p></p><div class="lightbox-wrapper"><a class="lightbox" href="https://global.discourse-cdn.com/standard17/uploads/redash1/original/2X/5/51b371d2a4b8bf53456bc14ddcf88e29e0c280c4.png" data-download-href="/uploads/short-url/bEL8gUHyKdhuxDvj58v3xF0pnPS.png?dl=1" title="image" rel="noopener nofollow ugc"><img src="https://global.discourse-cdn.com/standard17/uploads/redash1/original/2X/5/51b371d2a4b8bf53456bc14ddcf88e29e0c280c4.png" alt="image" data-base62-sha1="bEL8gUHyKdhuxDvj58v3xF0pnPS" width="690" height="457" data-small-upload="https://global.discourse-cdn.com/standard17/uploads/redash1/optimized/2X/5/51b371d2a4b8bf53456bc14ddcf88e29e0c280c4_2_10x10.png"></a></div><p></p>
<p></p><div class="lightbox-wrapper"><a class="lightbox" href="https://global.discourse-cdn.com/standard17/uploads/redash1/original/2X/2/221afa077e7a5db9c515705fdb0ad561a5806a26.png" data-download-href="/uploads/short-url/4RI1W9Rr3XneThIfHekR8X1tCCi.png?dl=1" title="image" rel="noopener nofollow ugc"><img src="https://global.discourse-cdn.com/standard17/uploads/redash1/original/2X/2/221afa077e7a5db9c515705fdb0ad561a5806a26.png" alt="image" data-base62-sha1="4RI1W9Rr3XneThIfHekR8X1tCCi" width="294" height="500" data-small-upload="https://global.discourse-cdn.com/standard17/uploads/redash1/optimized/2X/2/221afa077e7a5db9c515705fdb0ad561a5806a26_2_10x10.png"></a></div><p></p>
<p><img src="https://global.discourse-cdn.com/standard17/uploads/redash1/original/2X/1/1845246f2c8f191cb767db78b11e572ce3e25a72.png" alt="image" data-base62-sha1="3sHAX8UmgpJ7kDZRevgAED29vRE" width="639" height="297"></p>
          <p><a href="https://discuss.redash.io/t/upgrade-v8-v10-cant-login-to-redash-anymore/9562/2">Read full topic</a></p>
        ]]></description>
        <link>https://discuss.redash.io/t/upgrade-v8-v10-cant-login-to-redash-anymore/9562/2</link>
        <pubDate>Sat, 27 Nov 2021 13:25:44 +0000</pubDate>
        <guid isPermaLink="false">discuss.redash.io-post-9562-2</guid>
        <source url="https://discuss.redash.io/t/upgrade-v8-v10-cant-login-to-redash-anymore/9562.rss">Upgrade v8 -&gt; v10: Can&#39;t login to redash anymore</source>
      </item>
      <item>
        <title>Upgrade v8 -&gt; v10: Can&#39;t login to redash anymore</title>
        <dc:creator><![CDATA[Schmabudi]]></dc:creator>
        <description><![CDATA[
            <p>Hi there!</p>
<p>After my <a href="http://discuss.redash.io/t/i-cant-use-pandas-json-normalize-within-a-python-query/9560">initial problem</a>  I tried to upgrade redash from v8 to v10 and followed <a href="https://github.com/getredash/redash/releases/tag/v10.0.0" rel="noopener nofollow ugc">this instruction</a> very carefully. But since that I can’t login to redash anymore … If I open localhost:8888/login I get a <strong>“500 Internal Server Error”</strong> with the following response:</p>
<pre><code class="lang-auto">server_1            | [2021-11-27 11:55:15,819][PID:12][ERROR][redash.app] Exception on /login [GET]
server_1            | Traceback (most recent call last):
server_1            |   File "/usr/local/lib/python3.7/site-packages/sqlalchemy/engine/base.py", line 1249, in _execute_context
server_1            |     cursor, statement, parameters, context
server_1            |   File "/usr/local/lib/python3.7/site-packages/sqlalchemy/engine/default.py", line 580, in do_execute
server_1            |     cursor.execute(statement, parameters)
server_1            | psycopg2.errors.UndefinedTable: relation "organizations" does not exist
server_1            | LINE 2: FROM organizations
server_1            |              ^
server_1            |
server_1            |
server_1            | The above exception was the direct cause of the following exception:
server_1            |
server_1            | Traceback (most recent call last):
server_1            |   File "/usr/local/lib/python3.7/site-packages/flask/app.py", line 2446, in wsgi_app
server_1            |     response = self.full_dispatch_request()
server_1            |   File "/usr/local/lib/python3.7/site-packages/flask/app.py", line 1951, in full_dispatch_request
server_1            |     rv = self.handle_user_exception(e)
server_1            |   File "/usr/local/lib/python3.7/site-packages/flask_restful/__init__.py", line 269, in error_router
server_1            |     return original_handler(e)
server_1            |   File "/usr/local/lib/python3.7/site-packages/flask/app.py", line 1820, in handle_user_exception
server_1            |     reraise(exc_type, exc_value, tb)
server_1            |   File "/usr/local/lib/python3.7/site-packages/flask/_compat.py", line 39, in reraise
server_1            |     raise value
server_1            |   File "/usr/local/lib/python3.7/site-packages/flask/app.py", line 1949, in full_dispatch_request
server_1            |     rv = self.dispatch_request()
server_1            |   File "/usr/local/lib/python3.7/site-packages/flask/app.py", line 1935, in dispatch_request
server_1            |     return self.view_functions[rule.endpoint](**req.view_args)
server_1            |   File "/usr/local/lib/python3.7/site-packages/flask_limiter/extension.py", line 442, in __inner
server_1            |     return obj(*a, **k)
server_1            |   File "/app/redash/handlers/authentication.py", line 190, in login
server_1            |     if current_org == None and not settings.MULTI_ORG:
server_1            |   File "/usr/local/lib/python3.7/site-packages/werkzeug/local.py", line 370, in &lt;lambda&gt;
server_1            |     __eq__ = lambda x, o: x._get_current_object() == o
server_1            |   File "/usr/local/lib/python3.7/site-packages/werkzeug/local.py", line 307, in _get_current_object
server_1            |     return self.__local()
server_1            |   File "/app/redash/authentication/org_resolving.py", line 18, in _get_current_org
server_1            |     g.org = Organization.get_by_slug(slug)
server_1            |   File "/app/redash/models/organizations.py", line 31, in get_by_slug
server_1            |     return cls.query.filter(cls.slug == slug).first()
server_1            |   File "/usr/local/lib/python3.7/site-packages/sqlalchemy/orm/query.py", line 3240, in first
server_1            |     ret = list(self[0:1])
server_1            |   File "/usr/local/lib/python3.7/site-packages/sqlalchemy/orm/query.py", line 3018, in __getitem__server_1            |     return list(res)
server_1            |   File "/usr/local/lib/python3.7/site-packages/sqlalchemy/orm/query.py", line 3342, in __iter__
server_1            |     return self._execute_and_instances(context)
server_1            |   File "/usr/local/lib/python3.7/site-packages/sqlalchemy/orm/query.py", line 3367, in _execute_and_instances
server_1            |     result = conn.execute(querycontext.statement, self._params)
server_1            |   File "/usr/local/lib/python3.7/site-packages/sqlalchemy/engine/base.py", line 988, in execute
server_1            |     return meth(self, multiparams, params)
server_1            |   File "/usr/local/lib/python3.7/site-packages/sqlalchemy/sql/elements.py", line 287, in _execute_on_connection
server_1            |     return connection._execute_clauseelement(self, multiparams, params)
server_1            |   File "/usr/local/lib/python3.7/site-packages/sqlalchemy/engine/base.py", line 1107, in _execute_clauseelement
server_1            |     distilled_params,
server_1            |   File "/usr/local/lib/python3.7/site-packages/sqlalchemy/engine/base.py", line 1253, in _execute_context
server_1            |     e, statement, parameters, cursor, context
server_1            |   File "/usr/local/lib/python3.7/site-packages/sqlalchemy/engine/base.py", line 1473, in _handle_dbapi_exception
server_1            |     util.raise_from_cause(sqlalchemy_exception, exc_info)
server_1            |   File "/usr/local/lib/python3.7/site-packages/sqlalchemy/util/compat.py", line 398, in raise_from_cause
server_1            |     reraise(type(exception), exception, tb=exc_tb, cause=cause)
server_1            |   File "/usr/local/lib/python3.7/site-packages/sqlalchemy/util/compat.py", line 152, in reraise
server_1            |     raise value.with_traceback(tb)
server_1            |   File "/usr/local/lib/python3.7/site-packages/sqlalchemy/engine/base.py", line 1249, in _execute_context
server_1            |     cursor, statement, parameters, context
server_1            |   File "/usr/local/lib/python3.7/site-packages/sqlalchemy/engine/default.py", line 580, in do_execute
server_1            |     cursor.execute(statement, parameters)
server_1            | sqlalchemy.exc.ProgrammingError: (psycopg2.errors.UndefinedTable) relation "organizations" does not exist
server_1            | LINE 2: FROM organizations
server_1            |              ^
server_1            |
server_1            | [SQL: SELECT organizations.updated_at AS organizations_updated_at, organizations.created_at AS organizations_created_at, organizations.id AS organizations_id, organizations.name AS organizations_name, organizations.slug AS organizations_slug, organizations.settings AS organizations_settings
server_1            | FROM organizations
server_1            | WHERE organizations.slug = %(slug_1)s
server_1            |  LIMIT %(param_1)s]
server_1            | [parameters: {'slug_1': 'default', 'param_1': 1}]
server_1            | (Background on this error at: http://sqlalche.me/e/f405)
server_1            | [2021-11-27 11:55:15,824][PID:12][INFO][metrics] method=GET path=/login endpoint=redash_login status=500 content_type=text/html content_length=290 duration=99.49 query_count=0 query_duration=0.00
server_1            | [2021-11-27 11:55:15,826][PID:12][INFO][metrics] method=GET path=/login endpoint=redash_login status=500 content_type=? content_length=-1 duration=101.18 query_count=0 query_duration=0.00
nginx_1             | 172.18.0.1 - - [27/Nov/2021:11:55:15 +0000] "GET /login?next=http%3A%2F%2Flocalhost%3A8888%2Ffavicon.ico HTTP/1.1" 500 290 "http://localhost:8888/login" "Mozilla/5.0 (Windows NT 10.0; Win64; x64) AppleWebKit/537.36 (KHTML, like Gecko) Chrome/96.0.4664.45 Safari/537.36" "-"
</code></pre>
<p>This is my docker-compose.yml:</p>
<pre><code class="lang-auto">version: "2"
x-redash-service: &amp;redash-service
  image: redash/redash:10.0.0.b50363
  depends_on:
    - postgres
    - redis
  env_file: G:\redash\.env
  restart: always
services:
  server:
    &lt;&lt;: *redash-service
    command: server
    ports:
      - "5000:5000"
    environment:
      REDASH_WEB_WORKERS: 4
  scheduler:
    &lt;&lt;: *redash-service
    command: scheduler
  scheduled_worker:
    &lt;&lt;: *redash-service
    command: worker
    environment:
      QUEUES: "scheduled_queries,schemas"
      WORKERS_COUNT: 1
  adhoc_worker:
    &lt;&lt;: *redash-service
    command: worker
    environment:
      QUEUES: "queries"
      WORKERS_COUNT: 2
  worker:
    &lt;&lt;: *redash-service
    command: worker
    environment:
      QUEUES: "periodic emails default"
      WORKERS_COUNT: 1      
  redis:
    image: redis:5.0-alpine
    restart: always
  postgres:
    image: postgres:9.6-alpine
    env_file: G:\redash\.env
    volumes:
      - /opt/redash/postgres-data:/var/lib/postgresql/data
    restart: always
  nginx:
    image: redash/nginx:latest
    ports:
      - "8888:80"
    depends_on:
      - server
    links:
      - server:redash
    restart: always
</code></pre>
<p>What am I doing wrong? I really appreciate your help! Thanks</p>
          <p><a href="https://discuss.redash.io/t/upgrade-v8-v10-cant-login-to-redash-anymore/9562/1">Read full topic</a></p>
        ]]></description>
        <link>https://discuss.redash.io/t/upgrade-v8-v10-cant-login-to-redash-anymore/9562/1</link>
        <pubDate>Sat, 27 Nov 2021 12:03:35 +0000</pubDate>
        <guid isPermaLink="false">discuss.redash.io-post-9562-1</guid>
        <source url="https://discuss.redash.io/t/upgrade-v8-v10-cant-login-to-redash-anymore/9562.rss">Upgrade v8 -&gt; v10: Can&#39;t login to redash anymore</source>
      </item>
  </channel>
</rss>
