<?xml version="1.0" encoding="UTF-8" ?>
<rss version="2.0" xmlns:atom="http://www.w3.org/2005/Atom" xmlns:dc="http://purl.org/dc/elements/1.1/">
  <channel>
    <title>ELK as Datasource Error</title>
    <link>https://discuss.redash.io/t/elk-as-datasource-error/9830</link>
    <description>Hello !

I&#39;m Trying add one ELK as a datasource 

The connection works good !

But When I try see the Schema show a error 

![image|690x330](upload://zpjniZoB9aqRU1Qs5hqq08Ky47i.png)


On the logs I&#39;ve the error below 
```
[2022-01-12 21:15:46,654][PID:5162][WARNING][ForkPoolWorker-56758] task_name=redash.tasks.refresh_schema task_id=3d1cb444-12aa-40d2-9c29-29ca957fe2cb Failed refreshing schema for the data source: Swapback

1/12/2022 6:15:46 PM Traceback (most recent call last):

1/12/2022 6:15:46 PM File &quot;/app/redash/tasks/queries.py&quot;, line 261, in refresh_schema

1/12/2022 6:15:46 PM ds.get_schema(refresh=True)

1/12/2022 6:15:46 PM File &quot;/app/redash/models/__init__.py&quot;, line 155, in get_schema

1/12/2022 6:15:46 PM schema = sorted(query_runner.get_schema(get_stats=refresh), key=lambda t: t[&#39;name&#39;])

1/12/2022 6:15:46 PM File &quot;/app/redash/query_runner/__init__.py&quot;, line 142, in get_schema

1/12/2022 6:15:46 PM self._get_tables(schema_dict)


1/12/2022 6:15:46 PM File &quot;/app/redash/query_runner/mssql.py&quot;, line 95, in _get_tables

1/12/2022 6:15:46 PM raise Exception(&quot;Failed getting schema.&quot;)

1/12/2022 6:15:46 PM Exception: Failed getting schema.

[2022-01-12 21:15:46,725][PID:5172][WARNING][ForkPoolWorker-56768] task_name=redash.tasks.refresh_schema task_id=f1a41e5e-d13f-46f3-8aae-5df50f599ab2 Failed refreshing schema for the data source: vpc

1/12/2022 6:15:46 PM Traceback (most recent call last):

1/12/2022 6:15:46 PM File &quot;/app/redash/tasks/queries.py&quot;, line 261, in refresh_schema

1/12/2022 6:15:46 PM ds.get_schema(refresh=True)

1/12/2022 6:15:46 PM File &quot;/app/redash/models/__init__.py&quot;, line 155, in get_schema

1/12/2022 6:15:46 PM schema = sorted(query_runner.get_schema(get_stats=refresh), key=lambda t: t[&#39;name&#39;])

1/12/2022 6:15:46 PM File &quot;/app/redash/query_runner/elasticsearch.py&quot;, line 173, in get_schema

1/12/2022 6:15:46 PM columns.extend(parse_doc(items))

1/12/2022 6:15:46 PM File &quot;/app/redash/query_runner/elasticsearch.py&quot;, line 154, in parse_doc

1/12/2022 6:15:46 PM for field, description in doc[&#39;properties&#39;].items():

1/12/2022 6:15:46 PM KeyError: &#39;properties&#39;

Traceback (most recent call last):

1/12/2022 6:15:46 PM File &quot;/app/redash/tasks/queries.py&quot;, line 261, in refresh_schema

1/12/2022 6:15:46 PM ds.get_schema(refresh=True)

1/12/2022 6:15:46 PM File &quot;/app/redash/models/__init__.py&quot;, line 155, in get_schema

1/12/2022 6:15:46 PM schema = sorted(query_runner.get_schema(get_stats=refresh), key=lambda t: t[&#39;name&#39;])

1/12/2022 6:15:46 PM File &quot;/app/redash/query_runner/mongodb.py&quot;, line 217, in get_schema

1/12/2022 6:15:46 PM columns = self._get_collection_fields(db, collection_name)

1/12/2022 6:15:46 PM File &quot;/app/redash/query_runner/mongodb.py&quot;, line 204, in _get_collection_fields

1/12/2022 6:15:46 PM for d in db[collection_name].find().sort([(&quot;$natural&quot;, -1)]).limit(1):

1/12/2022 6:15:46 PM File &quot;/usr/local/lib/python2.7/site-packages/pymongo/cursor.py&quot;, line 1169, in next

1/12/2022 6:15:46 PM if len(self.__data) or self._refresh():

1/12/2022 6:15:46 PM File &quot;/usr/local/lib/python2.7/site-packages/pymongo/cursor.py&quot;, line 1085, in _refresh

1/12/2022 6:15:46 PM self.__send_message(q)

1/12/2022 6:15:46 PM File &quot;/usr/local/lib/python2.7/site-packages/pymongo/cursor.py&quot;, line 975, in __send_message

1/12/2022 6:15:46 PM helpers._check_command_response(first)

1/12/2022 6:15:46 PM File &quot;/usr/local/lib/python2.7/site-packages/pymongo/helpers.py&quot;, line 145, in _check_command_response

1/12/2022 6:15:46 PM raise OperationFailure(msg % errmsg, code, response)

1/12/2022 6:15:46 PM OperationFailure: {$natural: -1} is not supported
```
Any ideas how to fix it ?</description>
    
    <lastBuildDate>Thu, 03 Feb 2022 22:03:40 +0000</lastBuildDate>
    <category>Support</category>
    <atom:link href="https://discuss.redash.io/t/elk-as-datasource-error/9830.rss" rel="self" type="application/rss+xml" />
      <item>
        <title>ELK as Datasource Error</title>
        <dc:creator><![CDATA[thiborges]]></dc:creator>
        <description><![CDATA[
            <p>Thanks Jesse…</p>
<p>I will try upgrade my version and test…</p>
<p>I let you know</p>
<p>Regards</p>
          <p><a href="https://discuss.redash.io/t/elk-as-datasource-error/9830/3">Read full topic</a></p>
        ]]></description>
        <link>https://discuss.redash.io/t/elk-as-datasource-error/9830/3</link>
        <pubDate>Thu, 03 Feb 2022 22:03:40 +0000</pubDate>
        <guid isPermaLink="false">discuss.redash.io-post-9830-3</guid>
        <source url="https://discuss.redash.io/t/elk-as-datasource-error/9830.rss">ELK as Datasource Error</source>
      </item>
      <item>
        <title>ELK as Datasource Error</title>
        <dc:creator><![CDATA[jesse]]></dc:creator>
        <description><![CDATA[
            <p>Hmmm I’m not familiar with the ELK query runner but this may be a version mismatch: i.e. Redash is expecting to query some version of ELK that’s different from yours. If this reproduces on V10 of Redash we can open an issue for it. It appears you’re running V8 which is no longer supported.</p>
          <p><a href="https://discuss.redash.io/t/elk-as-datasource-error/9830/2">Read full topic</a></p>
        ]]></description>
        <link>https://discuss.redash.io/t/elk-as-datasource-error/9830/2</link>
        <pubDate>Tue, 18 Jan 2022 21:14:49 +0000</pubDate>
        <guid isPermaLink="false">discuss.redash.io-post-9830-2</guid>
        <source url="https://discuss.redash.io/t/elk-as-datasource-error/9830.rss">ELK as Datasource Error</source>
      </item>
      <item>
        <title>ELK as Datasource Error</title>
        <dc:creator><![CDATA[thiborges]]></dc:creator>
        <description><![CDATA[
            <p>Hello !</p>
<p>I’m Trying add one ELK as a datasource</p>
<p>The connection works good !</p>
<p>But When I try see the Schema show a error</p>
<p></p><div class="lightbox-wrapper"><a class="lightbox" href="https://global.discourse-cdn.com/standard17/uploads/redash1/original/2X/f/f82896fcdcf5be3503025c398898b1398cf273a4.png" data-download-href="/uploads/short-url/zpjniZoB9aqRU1Qs5hqq08Ky47i.png?dl=1" title="image" rel="noopener nofollow ugc"><img src="https://global.discourse-cdn.com/standard17/uploads/redash1/optimized/2X/f/f82896fcdcf5be3503025c398898b1398cf273a4_2_690x330.png" alt="image" data-base62-sha1="zpjniZoB9aqRU1Qs5hqq08Ky47i" width="690" height="330" srcset="https://global.discourse-cdn.com/standard17/uploads/redash1/optimized/2X/f/f82896fcdcf5be3503025c398898b1398cf273a4_2_690x330.png, https://global.discourse-cdn.com/standard17/uploads/redash1/optimized/2X/f/f82896fcdcf5be3503025c398898b1398cf273a4_2_1035x495.png 1.5x, https://global.discourse-cdn.com/standard17/uploads/redash1/original/2X/f/f82896fcdcf5be3503025c398898b1398cf273a4.png 2x" data-small-upload="https://global.discourse-cdn.com/standard17/uploads/redash1/optimized/2X/f/f82896fcdcf5be3503025c398898b1398cf273a4_2_10x10.png"></a></div><p></p>
<p>On the logs I’ve the error below</p>
<pre><code class="lang-auto">[2022-01-12 21:15:46,654][PID:5162][WARNING][ForkPoolWorker-56758] task_name=redash.tasks.refresh_schema task_id=3d1cb444-12aa-40d2-9c29-29ca957fe2cb Failed refreshing schema for the data source: Swapback

1/12/2022 6:15:46 PM Traceback (most recent call last):

1/12/2022 6:15:46 PM File "/app/redash/tasks/queries.py", line 261, in refresh_schema

1/12/2022 6:15:46 PM ds.get_schema(refresh=True)

1/12/2022 6:15:46 PM File "/app/redash/models/__init__.py", line 155, in get_schema

1/12/2022 6:15:46 PM schema = sorted(query_runner.get_schema(get_stats=refresh), key=lambda t: t['name'])

1/12/2022 6:15:46 PM File "/app/redash/query_runner/__init__.py", line 142, in get_schema

1/12/2022 6:15:46 PM self._get_tables(schema_dict)


1/12/2022 6:15:46 PM File "/app/redash/query_runner/mssql.py", line 95, in _get_tables

1/12/2022 6:15:46 PM raise Exception("Failed getting schema.")

1/12/2022 6:15:46 PM Exception: Failed getting schema.

[2022-01-12 21:15:46,725][PID:5172][WARNING][ForkPoolWorker-56768] task_name=redash.tasks.refresh_schema task_id=f1a41e5e-d13f-46f3-8aae-5df50f599ab2 Failed refreshing schema for the data source: vpc

1/12/2022 6:15:46 PM Traceback (most recent call last):

1/12/2022 6:15:46 PM File "/app/redash/tasks/queries.py", line 261, in refresh_schema

1/12/2022 6:15:46 PM ds.get_schema(refresh=True)

1/12/2022 6:15:46 PM File "/app/redash/models/__init__.py", line 155, in get_schema

1/12/2022 6:15:46 PM schema = sorted(query_runner.get_schema(get_stats=refresh), key=lambda t: t['name'])

1/12/2022 6:15:46 PM File "/app/redash/query_runner/elasticsearch.py", line 173, in get_schema

1/12/2022 6:15:46 PM columns.extend(parse_doc(items))

1/12/2022 6:15:46 PM File "/app/redash/query_runner/elasticsearch.py", line 154, in parse_doc

1/12/2022 6:15:46 PM for field, description in doc['properties'].items():

1/12/2022 6:15:46 PM KeyError: 'properties'

Traceback (most recent call last):

1/12/2022 6:15:46 PM File "/app/redash/tasks/queries.py", line 261, in refresh_schema

1/12/2022 6:15:46 PM ds.get_schema(refresh=True)

1/12/2022 6:15:46 PM File "/app/redash/models/__init__.py", line 155, in get_schema

1/12/2022 6:15:46 PM schema = sorted(query_runner.get_schema(get_stats=refresh), key=lambda t: t['name'])

1/12/2022 6:15:46 PM File "/app/redash/query_runner/mongodb.py", line 217, in get_schema

1/12/2022 6:15:46 PM columns = self._get_collection_fields(db, collection_name)

1/12/2022 6:15:46 PM File "/app/redash/query_runner/mongodb.py", line 204, in _get_collection_fields

1/12/2022 6:15:46 PM for d in db[collection_name].find().sort([("$natural", -1)]).limit(1):

1/12/2022 6:15:46 PM File "/usr/local/lib/python2.7/site-packages/pymongo/cursor.py", line 1169, in next

1/12/2022 6:15:46 PM if len(self.__data) or self._refresh():

1/12/2022 6:15:46 PM File "/usr/local/lib/python2.7/site-packages/pymongo/cursor.py", line 1085, in _refresh

1/12/2022 6:15:46 PM self.__send_message(q)

1/12/2022 6:15:46 PM File "/usr/local/lib/python2.7/site-packages/pymongo/cursor.py", line 975, in __send_message

1/12/2022 6:15:46 PM helpers._check_command_response(first)

1/12/2022 6:15:46 PM File "/usr/local/lib/python2.7/site-packages/pymongo/helpers.py", line 145, in _check_command_response

1/12/2022 6:15:46 PM raise OperationFailure(msg % errmsg, code, response)

1/12/2022 6:15:46 PM OperationFailure: {$natural: -1} is not supported
</code></pre>
<p>Any ideas how to fix it ?</p>
          <p><a href="https://discuss.redash.io/t/elk-as-datasource-error/9830/1">Read full topic</a></p>
        ]]></description>
        <link>https://discuss.redash.io/t/elk-as-datasource-error/9830/1</link>
        <pubDate>Wed, 12 Jan 2022 21:33:42 +0000</pubDate>
        <guid isPermaLink="false">discuss.redash.io-post-9830-1</guid>
        <source url="https://discuss.redash.io/t/elk-as-datasource-error/9830.rss">ELK as Datasource Error</source>
      </item>
  </channel>
</rss>
