<?xml version="1.0" encoding="UTF-8" ?>
<rss version="2.0" xmlns:atom="http://www.w3.org/2005/Atom" xmlns:dc="http://purl.org/dc/elements/1.1/">
  <channel>
    <title>Redash datasource connection test fails</title>
    <link>https://discuss.redash.io/t/redash-datasource-connection-test-fails/9989</link>
    <description>### Issue Summary

redash datasource connection fails after redash running for a few days

### Technical details:
We are running redash using EKS.  After the application runs for several days, the datasources become reachable. Normally we can get the connections back after we restart the redash_adhocworker. But today, I cannot get any datasource connection back after I restarted the whole stack

* Redash Version:  11.0.0-dev
* Browser/OS: latest chrome or firefox
* How did you install Redash:   on EKS

The Datasource connection test fails with **error:**

Connection Test Failed:
Parameter validation failed: Unknown parameter in QueryExecutionContext: &quot;Catalog&quot;, must be one of: Database

I am not sure what parameter it is complaining about. I really appreciate it  If anyone can give any suggestion.


The redash adhocworker node  **log**:

```
[2022-02-09 21:05:52,698][PID:567][DEBUG][botocore.loaders] Loading JSON file: /usr/local/lib/python3.7/site-packages/botocore/data/_retry.json
[2022-02-09 21:05:52,699][PID:567][DEBUG][botocore.client] Registering retry handlers for service: athena
[2022-02-09 21:05:52,701][PID:567][DEBUG][pyathena.common] SELECT 1
[2022-02-09 21:05:52,702][PID:567][DEBUG][botocore.hooks] Event before-parameter-build.athena.StartQueryExecution: calling handler &lt;function generate_idempotent_uuid at 0x7f48866d7b90&gt;
[2022-02-09 21:05:52,702][PID:567][DEBUG][botocore.handlers] injecting idempotency token (e4beee30-0f20-43e3-843a-69ba2a5ff728) into param &#39;ClientRequestToken&#39;.
[2022-02-09 21:05:52,702][PID:567][ERROR][pyathena.common] Failed to execute query.
Traceback (most recent call last):
  File &quot;/usr/local/lib/python3.7/site-packages/pyathena/common.py&quot;, line 417, in _execute
    **request
  File &quot;/usr/local/lib/python3.7/site-packages/pyathena/util.py&quot;, line 84, in retry_api_call
    return retry(func, *args, **kwargs)
  File &quot;/usr/local/lib/python3.7/site-packages/tenacity/__init__.py&quot;, line 404, in __call__
    do = self.iter(retry_state=retry_state)
  File &quot;/usr/local/lib/python3.7/site-packages/tenacity/__init__.py&quot;, line 349, in iter
    return fut.result()
  File &quot;/usr/local/lib/python3.7/concurrent/futures/_base.py&quot;, line 428, in result
    return self.__get_result()
  File &quot;/usr/local/lib/python3.7/concurrent/futures/_base.py&quot;, line 384, in __get_result
    raise self._exception
  File &quot;/usr/local/lib/python3.7/site-packages/tenacity/__init__.py&quot;, line 407, in __call__
    result = fn(*args, **kwargs)
  File &quot;/usr/local/lib/python3.7/site-packages/botocore/client.py&quot;, line 276, in _api_call
    return self._make_api_call(operation_name, kwargs)
  File &quot;/usr/local/lib/python3.7/site-packages/botocore/client.py&quot;, line 559, in _make_api_call
    api_params, operation_model, context=request_context)
  File &quot;/usr/local/lib/python3.7/site-packages/botocore/client.py&quot;, line 607, in _convert_to_request_dict
    api_params, operation_model)
  File &quot;/usr/local/lib/python3.7/site-packages/botocore/validate.py&quot;, line 297, in serialize_to_request
    raise ParamValidationError(report=report.generate_report())
botocore.exceptions.ParamValidationError: Parameter validation failed:
Unknown parameter in QueryExecutionContext: &quot;Catalog&quot;, must be one of: Database
[2022-02-09 21:05:52,756][PID:567][INFO][rq.worker] queries: Job OK (0491b875-2751-44cc-a4a2-6a5a50a66e56)

```</description>
    
    <lastBuildDate>Thu, 23 Feb 2023 20:02:31 +0000</lastBuildDate>
    <category>Self Hosted Redash Support</category>
    <atom:link href="https://discuss.redash.io/t/redash-datasource-connection-test-fails/9989.rss" rel="self" type="application/rss+xml" />
      <item>
        <title>Redash datasource connection test fails</title>
        <dc:creator><![CDATA[zachliu]]></dc:creator>
        <description><![CDATA[
            <aside class="onebox githubpullrequest" data-onebox-src="https://github.com/getredash/redash/pull/5898">
  <header class="source">

      <a href="https://github.com/getredash/redash/pull/5898" target="_blank" rel="noopener nofollow ugc">github.com/getredash/redash</a>
  </header>

  <article class="onebox-body">
    <div class="github-row">



    <div class="github-icon-container" title="Pull Request">
      <svg width="60" height="60" class="github-icon" viewBox="0 0 12 16" aria-hidden="true"><path fill-rule="evenodd" d="M11 11.28V5c-.03-.78-.34-1.47-.94-2.06C9.46 2.35 8.78 2.03 8 2H7V0L4 3l3 3V4h1c.27.02.48.11.69.31.21.2.3.42.31.69v6.28A1.993 1.993 0 0 0 10 15a1.993 1.993 0 0 0 1-3.72zm-1 2.92c-.66 0-1.2-.55-1.2-1.2 0-.65.55-1.2 1.2-1.2.65 0 1.2.55 1.2 1.2 0 .65-.55 1.2-1.2 1.2zM4 3c0-1.11-.89-2-2-2a1.993 1.993 0 0 0-1 3.72v6.56A1.993 1.993 0 0 0 2 15a1.993 1.993 0 0 0 1-3.72V4.72c.59-.34 1-.98 1-1.72zm-.8 10c0 .66-.55 1.2-1.2 1.2-.65 0-1.2-.55-1.2-1.2 0-.65.55-1.2 1.2-1.2.65 0 1.2.55 1.2 1.2zM2 4.2C1.34 4.2.8 3.65.8 3c0-.65.55-1.2 1.2-1.2.65 0 1.2.55 1.2 1.2 0 .65-.55 1.2-1.2 1.2z"></path></svg>
    </div>

  <div class="github-info-container">



      <h4>
        <a href="https://github.com/getredash/redash/pull/5898" target="_blank" rel="noopener nofollow ugc">upper limit on pyathena</a>
      </h4>

    <div class="branches">
      <code>getredash:master</code> ← <code>zachliu:fix-pyathena-version</code>
    </div>

      <div class="github-info">
        <div class="date">
          opened <span class="discourse-local-date" data-format="ll" data-date="2023-02-23" data-time="20:02:12" data-timezone="UTC">08:02PM - 23 Feb 23 UTC</span>
        </div>

        <div class="user">
          <a href="https://github.com/zachliu" target="_blank" rel="noopener nofollow ugc">
            <img alt="zachliu" src="https://avatars.githubusercontent.com/u/14293802?v=4" class="onebox-avatar-inline" width="20" height="20">
            zachliu
          </a>
        </div>

        <div class="lines" title="1 commits changed 2 files with 3 additions and 3 deletions">
          <a href="https://github.com/getredash/redash/pull/5898/files" target="_blank" rel="noopener nofollow ugc">
            <span class="added">+3</span>
            <span class="removed">-3</span>
          </a>
        </div>
      </div>
  </div>
</div>

  <div class="github-row">
    <p class="github-body-container">See [here](https://discuss.redash.io/t/redash-datasource-connection-test-fails/9<span class="show-more-container"><a href="https://github.com/getredash/redash/pull/5898" target="_blank" rel="noopener nofollow ugc" class="show-more">…</a></span><span class="excerpt hidden">989)

## What type of PR is this? 


- [ ] Refactor
- [ ] Feature
- [ ] Bug Fix
- [ ] New Query Runner (Data Source) 
- [ ] New Alert Destination
- [ ] Other

## Description


## How is this tested?

- [ ] Unit tests (pytest, jest)
- [ ] E2E Tests (Cypress)
- [ ] Manually
- [ ] N/A



## Related Tickets &amp; Documents


## Mobile &amp; Desktop Screenshots/Recordings (if there are UI changes)</span></p>
  </div>

  </article>

  <div class="onebox-metadata">
    
    
  </div>

  <div style="clear: both"></div>
</aside>

          <p><a href="https://discuss.redash.io/t/redash-datasource-connection-test-fails/9989/5">Read full topic</a></p>
        ]]></description>
        <link>https://discuss.redash.io/t/redash-datasource-connection-test-fails/9989/5</link>
        <pubDate>Thu, 23 Feb 2023 20:02:31 +0000</pubDate>
        <guid isPermaLink="false">discuss.redash.io-post-9989-5</guid>
        <source url="https://discuss.redash.io/t/redash-datasource-connection-test-fails/9989.rss">Redash datasource connection test fails</source>
      </item>
      <item>
        <title>Redash datasource connection test fails</title>
        <dc:creator><![CDATA[zachliu]]></dc:creator>
        <description><![CDATA[
            <p><img src="https://emoji.discourse-cdn.com/twitter/+1.png?v=12" title=":+1:" class="emoji" alt=":+1:" loading="lazy" width="20" height="20"> i hereby confirm this works! without it, PyAthena would be upgraded to the latest version causing that error</p>
<pre><code class="lang-auto">#15 8.298 Collecting PyAthena&gt;=1.5.0
#15 8.302   Downloading pyathena-2.21.0-py3-none-any.whl (67 kB)
</code></pre>
          <p><a href="https://discuss.redash.io/t/redash-datasource-connection-test-fails/9989/4">Read full topic</a></p>
        ]]></description>
        <link>https://discuss.redash.io/t/redash-datasource-connection-test-fails/9989/4</link>
        <pubDate>Thu, 23 Feb 2023 19:59:29 +0000</pubDate>
        <guid isPermaLink="false">discuss.redash.io-post-9989-4</guid>
        <source url="https://discuss.redash.io/t/redash-datasource-connection-test-fails/9989.rss">Redash datasource connection test fails</source>
      </item>
      <item>
        <title>Redash datasource connection test fails</title>
        <dc:creator><![CDATA[jesse]]></dc:creator>
        <description><![CDATA[
            <p>Thanks for posting this. We’re happy to review a Pull Request implementing a fix if you’re so inclined <img src="https://emoji.discourse-cdn.com/twitter/pray.png?v=12" title=":pray:" class="emoji" alt=":pray:" loading="lazy" width="20" height="20"></p>
          <p><a href="https://discuss.redash.io/t/redash-datasource-connection-test-fails/9989/3">Read full topic</a></p>
        ]]></description>
        <link>https://discuss.redash.io/t/redash-datasource-connection-test-fails/9989/3</link>
        <pubDate>Mon, 04 Apr 2022 18:05:51 +0000</pubDate>
        <guid isPermaLink="false">discuss.redash.io-post-9989-3</guid>
        <source url="https://discuss.redash.io/t/redash-datasource-connection-test-fails/9989.rss">Redash datasource connection test fails</source>
      </item>
      <item>
        <title>Redash datasource connection test fails</title>
        <dc:creator><![CDATA[kzk-maeda]]></dc:creator>
        <description><![CDATA[
            <p>I’ve found the same issue.<br>
As I explored some codes, this seems to be caused by PyAthena, not Redash.</p>
<p>I guess this trouble is occurred in <a href="https://github.com/getredash/redash/blob/e6ebef1e5ab866ce1e706eaee6260edaffdc2bd7/redash/query_runner/athena.py#L232" rel="noopener nofollow ugc">here</a>, and I was able to get around it by changing <a href="https://github.com/getredash/redash/blob/e6ebef1e5ab866ce1e706eaee6260edaffdc2bd7/requirements_all_ds.txt#L24" rel="noopener nofollow ugc">specified version of PyAthena</a> as below.</p>
<pre><code class="lang-auto">PyAthena&gt;=1.5.0,&lt;=1.11.5
</code></pre>
<p>I’m going to seek more efficient solution or create Pull Request for quick fix.</p>
<p>I hope this is helpful for you.</p>
          <p><a href="https://discuss.redash.io/t/redash-datasource-connection-test-fails/9989/2">Read full topic</a></p>
        ]]></description>
        <link>https://discuss.redash.io/t/redash-datasource-connection-test-fails/9989/2</link>
        <pubDate>Sat, 02 Apr 2022 15:23:30 +0000</pubDate>
        <guid isPermaLink="false">discuss.redash.io-post-9989-2</guid>
        <source url="https://discuss.redash.io/t/redash-datasource-connection-test-fails/9989.rss">Redash datasource connection test fails</source>
      </item>
      <item>
        <title>Redash datasource connection test fails</title>
        <dc:creator><![CDATA[billchen]]></dc:creator>
        <description><![CDATA[
            <h3>
<a name="issue-summary-1" class="anchor" href="https://discuss.redash.io#issue-summary-1"></a>Issue Summary</h3>
<p>redash datasource connection fails after redash running for a few days</p>
<h3>
<a name="technical-details-2" class="anchor" href="https://discuss.redash.io#technical-details-2"></a>Technical details:</h3>
<p>We are running redash using EKS.  After the application runs for several days, the datasources become reachable. Normally we can get the connections back after we restart the redash_adhocworker. But today, I cannot get any datasource connection back after I restarted the whole stack</p>
<ul>
<li>Redash Version:  11.0.0-dev</li>
<li>Browser/OS: latest chrome or firefox</li>
<li>How did you install Redash:   on EKS</li>
</ul>
<p>The Datasource connection test fails with <strong>error:</strong></p>
<p>Connection Test Failed:<br>
Parameter validation failed: Unknown parameter in QueryExecutionContext: “Catalog”, must be one of: Database</p>
<p>I am not sure what parameter it is complaining about. I really appreciate it  If anyone can give any suggestion.</p>
<p>The redash adhocworker node  <strong>log</strong>:</p>
<pre><code class="lang-auto">[2022-02-09 21:05:52,698][PID:567][DEBUG][botocore.loaders] Loading JSON file: /usr/local/lib/python3.7/site-packages/botocore/data/_retry.json
[2022-02-09 21:05:52,699][PID:567][DEBUG][botocore.client] Registering retry handlers for service: athena
[2022-02-09 21:05:52,701][PID:567][DEBUG][pyathena.common] SELECT 1
[2022-02-09 21:05:52,702][PID:567][DEBUG][botocore.hooks] Event before-parameter-build.athena.StartQueryExecution: calling handler &lt;function generate_idempotent_uuid at 0x7f48866d7b90&gt;
[2022-02-09 21:05:52,702][PID:567][DEBUG][botocore.handlers] injecting idempotency token (e4beee30-0f20-43e3-843a-69ba2a5ff728) into param 'ClientRequestToken'.
[2022-02-09 21:05:52,702][PID:567][ERROR][pyathena.common] Failed to execute query.
Traceback (most recent call last):
  File "/usr/local/lib/python3.7/site-packages/pyathena/common.py", line 417, in _execute
    **request
  File "/usr/local/lib/python3.7/site-packages/pyathena/util.py", line 84, in retry_api_call
    return retry(func, *args, **kwargs)
  File "/usr/local/lib/python3.7/site-packages/tenacity/__init__.py", line 404, in __call__
    do = self.iter(retry_state=retry_state)
  File "/usr/local/lib/python3.7/site-packages/tenacity/__init__.py", line 349, in iter
    return fut.result()
  File "/usr/local/lib/python3.7/concurrent/futures/_base.py", line 428, in result
    return self.__get_result()
  File "/usr/local/lib/python3.7/concurrent/futures/_base.py", line 384, in __get_result
    raise self._exception
  File "/usr/local/lib/python3.7/site-packages/tenacity/__init__.py", line 407, in __call__
    result = fn(*args, **kwargs)
  File "/usr/local/lib/python3.7/site-packages/botocore/client.py", line 276, in _api_call
    return self._make_api_call(operation_name, kwargs)
  File "/usr/local/lib/python3.7/site-packages/botocore/client.py", line 559, in _make_api_call
    api_params, operation_model, context=request_context)
  File "/usr/local/lib/python3.7/site-packages/botocore/client.py", line 607, in _convert_to_request_dict
    api_params, operation_model)
  File "/usr/local/lib/python3.7/site-packages/botocore/validate.py", line 297, in serialize_to_request
    raise ParamValidationError(report=report.generate_report())
botocore.exceptions.ParamValidationError: Parameter validation failed:
Unknown parameter in QueryExecutionContext: "Catalog", must be one of: Database
[2022-02-09 21:05:52,756][PID:567][INFO][rq.worker] queries: Job OK (0491b875-2751-44cc-a4a2-6a5a50a66e56)

</code></pre>
          <p><a href="https://discuss.redash.io/t/redash-datasource-connection-test-fails/9989/1">Read full topic</a></p>
        ]]></description>
        <link>https://discuss.redash.io/t/redash-datasource-connection-test-fails/9989/1</link>
        <pubDate>Wed, 09 Feb 2022 21:29:20 +0000</pubDate>
        <guid isPermaLink="false">discuss.redash.io-post-9989-1</guid>
        <source url="https://discuss.redash.io/t/redash-datasource-connection-test-fails/9989.rss">Redash datasource connection test fails</source>
      </item>
  </channel>
</rss>
