<?xml version="1.0" encoding="UTF-8" ?>
<rss version="2.0" xmlns:atom="http://www.w3.org/2005/Atom" xmlns:dc="http://purl.org/dc/elements/1.1/">
  <channel>
    <title>Can&#39;t connect to Google BigQuery with 500 error</title>
    <link>https://discuss.redash.io/t/cant-connect-to-google-bigquery-with-500-error/10323</link>
    <description>### Issue Summary

I tried to connect BigQuery but it does not allow me to connect using Service Account. I tested with different clients, such as DataGrip or Postico, and it does work fine on that. 
The error message that I get is 
```
server_1     | Traceback (most recent call last):
server_1     |   File &quot;/usr/local/lib/python3.7/site-packages/flask/app.py&quot;, line 2463, in __call__
server_1     |     return self.wsgi_app(environ, start_response)
server_1     |   File &quot;/usr/local/lib/python3.7/site-packages/werkzeug/middleware/proxy_fix.py&quot;, line 232, in __call__
server_1     |     return self.app(environ, start_response)
server_1     |   File &quot;/usr/local/lib/python3.7/site-packages/flask/app.py&quot;, line 2449, in wsgi_app
server_1     |     response = self.handle_exception(e)
server_1     |   File &quot;/usr/local/lib/python3.7/site-packages/flask_restful/__init__.py&quot;, line 269, in error_router
server_1     |     return original_handler(e)
server_1     |   File &quot;/usr/local/lib/python3.7/site-packages/flask/app.py&quot;, line 1866, in handle_exception
server_1     |     reraise(exc_type, exc_value, tb)
server_1     |   File &quot;/usr/local/lib/python3.7/site-packages/flask/_compat.py&quot;, line 38, in reraise
server_1     |     raise value.with_traceback(tb)
server_1     |   File &quot;/usr/local/lib/python3.7/site-packages/flask/app.py&quot;, line 2446, in wsgi_app
server_1     |     response = self.full_dispatch_request()
server_1     |   File &quot;/usr/local/lib/python3.7/site-packages/flask/app.py&quot;, line 1951, in full_dispatch_request
server_1     |     rv = self.handle_user_exception(e)
server_1     |   File &quot;/usr/local/lib/python3.7/site-packages/flask_restful/__init__.py&quot;, line 269, in error_router
server_1     |     return original_handler(e)
server_1     |   File &quot;/usr/local/lib/python3.7/site-packages/flask/app.py&quot;, line 1820, in handle_user_exception
server_1     |     reraise(exc_type, exc_value, tb)
server_1     |   File &quot;/usr/local/lib/python3.7/site-packages/flask/_compat.py&quot;, line 38, in reraise
server_1     |     raise value.with_traceback(tb)
server_1     |   File &quot;/usr/local/lib/python3.7/site-packages/flask/app.py&quot;, line 1949, in full_dispatch_request
server_1     |     rv = self.dispatch_request()
server_1     |   File &quot;/usr/local/lib/python3.7/site-packages/flask/app.py&quot;, line 1935, in dispatch_request
server_1     |     return self.view_functions[rule.endpoint](**req.view_args)
server_1     |   File &quot;/usr/local/lib/python3.7/site-packages/flask_restful/__init__.py&quot;, line 458, in wrapper
server_1     |     resp = resource(*args, **kwargs)
server_1     |   File &quot;/usr/local/lib/python3.7/site-packages/flask_login/utils.py&quot;, line 261, in decorated_view
server_1     |     return func(*args, **kwargs)
server_1     |   File &quot;/usr/local/lib/python3.7/site-packages/flask/views.py&quot;, line 89, in view
server_1     |     return self.dispatch_request(*args, **kwargs)
server_1     |   File &quot;/app/redash/handlers/base.py&quot;, line 33, in dispatch_request
server_1     |     return super(BaseResource, self).dispatch_request(*args, **kwargs)
server_1     |   File &quot;/usr/local/lib/python3.7/site-packages/flask_restful/__init__.py&quot;, line 573, in dispatch_request
server_1     |     resp = meth(*args, **kwargs)
server_1     |   File &quot;/app/redash/handlers/query_results.py&quot;, line 462, in get
server_1     |     job = Job.fetch(job_id)
server_1     |   File &quot;/usr/local/lib/python3.7/site-packages/rq/job.py&quot;, line 299, in fetch
server_1     |     job.refresh()
server_1     |   File &quot;/usr/local/lib/python3.7/site-packages/rq/job.py&quot;, line 518, in refresh
server_1     |     raise NoSuchJobError(&#39;No such job: {0}&#39;.format(self.key))
server_1     | rq.exceptions.NoSuchJobError: No such job: b&#39;rq:job:9e3e92ef-f01b-4983-a2a8-37edeb82d6c6&#39;
```

Does anyone have any ideas? what could be the issue?
I checked the issue here http://discuss.redash.io/t/redash-cant-connect-any-datasource/7146 and I already restarted the radis but it&#39;s not loading.

Thank you for your helps.

### Technical details:

* Redash Version:10.1.0
* Browser/OS:Chrome/MacOS (M1 silicon)
* How did you install Redash:Docker</description>
    
    <lastBuildDate>Fri, 15 Apr 2022 23:17:50 +0000</lastBuildDate>
    <category>Self Hosted Redash Support</category>
    <atom:link href="https://discuss.redash.io/t/cant-connect-to-google-bigquery-with-500-error/10323.rss" rel="self" type="application/rss+xml" />
      <item>
        <title>Can&#39;t connect to Google BigQuery with 500 error</title>
        <dc:creator><![CDATA[poke]]></dc:creator>
        <description><![CDATA[
            <p>Quickly tested with CSV data source and itâ€™s also failing. Any suggested options that I can try?</p>
          <p><a href="https://discuss.redash.io/t/cant-connect-to-google-bigquery-with-500-error/10323/3">Read full topic</a></p>
        ]]></description>
        <link>https://discuss.redash.io/t/cant-connect-to-google-bigquery-with-500-error/10323/3</link>
        <pubDate>Fri, 15 Apr 2022 23:17:50 +0000</pubDate>
        <guid isPermaLink="false">discuss.redash.io-post-10323-3</guid>
        <source url="https://discuss.redash.io/t/cant-connect-to-google-bigquery-with-500-error/10323.rss">Can&#39;t connect to Google BigQuery with 500 error</source>
      </item>
      <item>
        <title>Can&#39;t connect to Google BigQuery with 500 error</title>
        <dc:creator><![CDATA[jesse]]></dc:creator>
        <description><![CDATA[
            <p>Are you able to create and run queries against <em>any</em> data source? You can use the Query Results Data Source as a control just to be certain.</p>
          <p><a href="https://discuss.redash.io/t/cant-connect-to-google-bigquery-with-500-error/10323/2">Read full topic</a></p>
        ]]></description>
        <link>https://discuss.redash.io/t/cant-connect-to-google-bigquery-with-500-error/10323/2</link>
        <pubDate>Fri, 15 Apr 2022 22:19:00 +0000</pubDate>
        <guid isPermaLink="false">discuss.redash.io-post-10323-2</guid>
        <source url="https://discuss.redash.io/t/cant-connect-to-google-bigquery-with-500-error/10323.rss">Can&#39;t connect to Google BigQuery with 500 error</source>
      </item>
      <item>
        <title>Can&#39;t connect to Google BigQuery with 500 error</title>
        <dc:creator><![CDATA[poke]]></dc:creator>
        <description><![CDATA[
            <h3>
<a name="issue-summary-1" class="anchor" href="https://discuss.redash.io#issue-summary-1"></a>Issue Summary</h3>
<p>I tried to connect BigQuery but it does not allow me to connect using Service Account. I tested with different clients, such as DataGrip or Postico, and it does work fine on that.<br>
The error message that I get is</p>
<pre><code class="lang-auto">server_1     | Traceback (most recent call last):
server_1     |   File "/usr/local/lib/python3.7/site-packages/flask/app.py", line 2463, in __call__
server_1     |     return self.wsgi_app(environ, start_response)
server_1     |   File "/usr/local/lib/python3.7/site-packages/werkzeug/middleware/proxy_fix.py", line 232, in __call__
server_1     |     return self.app(environ, start_response)
server_1     |   File "/usr/local/lib/python3.7/site-packages/flask/app.py", line 2449, in wsgi_app
server_1     |     response = self.handle_exception(e)
server_1     |   File "/usr/local/lib/python3.7/site-packages/flask_restful/__init__.py", line 269, in error_router
server_1     |     return original_handler(e)
server_1     |   File "/usr/local/lib/python3.7/site-packages/flask/app.py", line 1866, in handle_exception
server_1     |     reraise(exc_type, exc_value, tb)
server_1     |   File "/usr/local/lib/python3.7/site-packages/flask/_compat.py", line 38, in reraise
server_1     |     raise value.with_traceback(tb)
server_1     |   File "/usr/local/lib/python3.7/site-packages/flask/app.py", line 2446, in wsgi_app
server_1     |     response = self.full_dispatch_request()
server_1     |   File "/usr/local/lib/python3.7/site-packages/flask/app.py", line 1951, in full_dispatch_request
server_1     |     rv = self.handle_user_exception(e)
server_1     |   File "/usr/local/lib/python3.7/site-packages/flask_restful/__init__.py", line 269, in error_router
server_1     |     return original_handler(e)
server_1     |   File "/usr/local/lib/python3.7/site-packages/flask/app.py", line 1820, in handle_user_exception
server_1     |     reraise(exc_type, exc_value, tb)
server_1     |   File "/usr/local/lib/python3.7/site-packages/flask/_compat.py", line 38, in reraise
server_1     |     raise value.with_traceback(tb)
server_1     |   File "/usr/local/lib/python3.7/site-packages/flask/app.py", line 1949, in full_dispatch_request
server_1     |     rv = self.dispatch_request()
server_1     |   File "/usr/local/lib/python3.7/site-packages/flask/app.py", line 1935, in dispatch_request
server_1     |     return self.view_functions[rule.endpoint](**req.view_args)
server_1     |   File "/usr/local/lib/python3.7/site-packages/flask_restful/__init__.py", line 458, in wrapper
server_1     |     resp = resource(*args, **kwargs)
server_1     |   File "/usr/local/lib/python3.7/site-packages/flask_login/utils.py", line 261, in decorated_view
server_1     |     return func(*args, **kwargs)
server_1     |   File "/usr/local/lib/python3.7/site-packages/flask/views.py", line 89, in view
server_1     |     return self.dispatch_request(*args, **kwargs)
server_1     |   File "/app/redash/handlers/base.py", line 33, in dispatch_request
server_1     |     return super(BaseResource, self).dispatch_request(*args, **kwargs)
server_1     |   File "/usr/local/lib/python3.7/site-packages/flask_restful/__init__.py", line 573, in dispatch_request
server_1     |     resp = meth(*args, **kwargs)
server_1     |   File "/app/redash/handlers/query_results.py", line 462, in get
server_1     |     job = Job.fetch(job_id)
server_1     |   File "/usr/local/lib/python3.7/site-packages/rq/job.py", line 299, in fetch
server_1     |     job.refresh()
server_1     |   File "/usr/local/lib/python3.7/site-packages/rq/job.py", line 518, in refresh
server_1     |     raise NoSuchJobError('No such job: {0}'.format(self.key))
server_1     | rq.exceptions.NoSuchJobError: No such job: b'rq:job:9e3e92ef-f01b-4983-a2a8-37edeb82d6c6'
</code></pre>
<p>Does anyone have any ideas? what could be the issue?<br>
I checked the issue here <a href="http://discuss.redash.io/t/redash-cant-connect-any-datasource/7146" class="inline-onebox">Redash can't connect any datasource</a> and I already restarted the radis but itâ€™s not loading.</p>
<p>Thank you for your helps.</p>
<h3>
<a name="technical-details-2" class="anchor" href="https://discuss.redash.io#technical-details-2"></a>Technical details:</h3>
<ul>
<li>Redash Version:10.1.0</li>
<li>Browser/OS:Chrome/MacOS (M1 silicon)</li>
<li>How did you install Redash:Docker</li>
</ul>
          <p><a href="https://discuss.redash.io/t/cant-connect-to-google-bigquery-with-500-error/10323/1">Read full topic</a></p>
        ]]></description>
        <link>https://discuss.redash.io/t/cant-connect-to-google-bigquery-with-500-error/10323/1</link>
        <pubDate>Fri, 15 Apr 2022 20:50:50 +0000</pubDate>
        <guid isPermaLink="false">discuss.redash.io-post-10323-1</guid>
        <source url="https://discuss.redash.io/t/cant-connect-to-google-bigquery-with-500-error/10323.rss">Can&#39;t connect to Google BigQuery with 500 error</source>
      </item>
  </channel>
</rss>
