<?xml version="1.0" encoding="UTF-8" ?>
<rss version="2.0" xmlns:atom="http://www.w3.org/2005/Atom" xmlns:dc="http://purl.org/dc/elements/1.1/">
  <channel>
    <title>Unknown error occurred while performing connection test</title>
    <link>https://discuss.redash.io/t/unknown-error-occurred-while-performing-connection-test/9411</link>
    <description>Hi Team,

I try to save the details of the DB connection properties and click on Test Connection, then I get error: Unknown error occurred while performing connection test. Please try again later&quot;
I can ping to Mysql DB from my terminal and the DB connection properties are correct.

Could somebody please help me what is causing the problem?

Thanks &amp; Regards,
Adam</description>
    
    <lastBuildDate>Sat, 27 Nov 2021 17:43:19 +0000</lastBuildDate>
    <category>Self Hosted Redash Support</category>
    <atom:link href="https://discuss.redash.io/t/unknown-error-occurred-while-performing-connection-test/9411.rss" rel="self" type="application/rss+xml" />
      <item>
        <title>Unknown error occurred while performing connection test</title>
        <dc:creator><![CDATA[adam09066]]></dc:creator>
        <description><![CDATA[
            <p>There was a little knowledge gap in Docker containers.</p>
          <p><a href="https://discuss.redash.io/t/unknown-error-occurred-while-performing-connection-test/9411/20">Read full topic</a></p>
        ]]></description>
        <link>https://discuss.redash.io/t/unknown-error-occurred-while-performing-connection-test/9411/20</link>
        <pubDate>Sat, 27 Nov 2021 17:43:19 +0000</pubDate>
        <guid isPermaLink="false">discuss.redash.io-post-9411-20</guid>
        <source url="https://discuss.redash.io/t/unknown-error-occurred-while-performing-connection-test/9411.rss">Unknown error occurred while performing connection test</source>
      </item>
      <item>
        <title>Unknown error occurred while performing connection test</title>
        <dc:creator><![CDATA[adam09066]]></dc:creator>
        <description><![CDATA[
            <p>Yes i did found the solution. The first image overwrote the second image and the second image did not contained the requirements. Therefore the Redash did not work correctly.</p>
<p>Sorry, next time I will keep the post.</p>
          <p><a href="https://discuss.redash.io/t/unknown-error-occurred-while-performing-connection-test/9411/19">Read full topic</a></p>
        ]]></description>
        <link>https://discuss.redash.io/t/unknown-error-occurred-while-performing-connection-test/9411/19</link>
        <pubDate>Sat, 27 Nov 2021 17:37:03 +0000</pubDate>
        <guid isPermaLink="false">discuss.redash.io-post-9411-19</guid>
        <source url="https://discuss.redash.io/t/unknown-error-occurred-while-performing-connection-test/9411.rss">Unknown error occurred while performing connection test</source>
      </item>
      <item>
        <title>Unknown error occurred while performing connection test</title>
        <dc:creator><![CDATA[jesse]]></dc:creator>
        <description><![CDATA[
            <p>Hi <a class="mention" href="https://discuss.redash.io/u/adam09066">@adam09066</a> - did you solve this issue? I see you deleted a post before I could respond to you. If you found a solution on your own, please share it rather than deleting your question.</p>
          <p><a href="https://discuss.redash.io/t/unknown-error-occurred-while-performing-connection-test/9411/18">Read full topic</a></p>
        ]]></description>
        <link>https://discuss.redash.io/t/unknown-error-occurred-while-performing-connection-test/9411/18</link>
        <pubDate>Sat, 27 Nov 2021 01:52:25 +0000</pubDate>
        <guid isPermaLink="false">discuss.redash.io-post-9411-18</guid>
        <source url="https://discuss.redash.io/t/unknown-error-occurred-while-performing-connection-test/9411.rss">Unknown error occurred while performing connection test</source>
      </item>
      <item>
        <title>Unknown error occurred while performing connection test</title>
        <dc:creator><![CDATA[adam09066]]></dc:creator>
        <description><![CDATA[
            <p>I am not familiar with Docker and Docker-compose yet. <img src="https://emoji.discourse-cdn.com/twitter/slight_smile.png?v=10" title=":slight_smile:" class="emoji" alt=":slight_smile:">  I would like to use Mysql and Oracle data sources in Redash. For Oracle settings, I set the following settings:</p>
<aside class="quote quote-modified" data-post="6" data-topic="4590">
  <div class="title">
    <div class="quote-controls"></div>
    <img loading="lazy" alt="" width="20" height="20" src="https://avatars.discourse-cdn.com/v4/letter/d/3ab097/40.png" class="avatar">
    <a href="http://discuss.redash.io/t/add-oracle-as-data-souce-to-redash/4590/6">Add oracle as data souce to redash</a> <a class="badge-wrapper  bullet" href="https://discuss.redash.io/c/support/support-self-hosted/9"><span class="badge-category-parent-bg" style="background-color: #BF1E2E;"></span><span class="badge-category-bg" style="background-color: #AB9364;"></span><span style="" data-drop-close="true" class="badge-category clear-badge" title="Support on installing, configuring and troubleshooting issues with self hosted Redash.">Self Hosted Redash Support</span></a>
  </div>
  <blockquote>
    Yiipieee I finally got it working <img width="20" height="20" src="https://emoji.discourse-cdn.com/twitter/slight_smile.png?v=10" title="slight_smile" alt="slight_smile" class="emoji"> . 
I tried everything to get it working but the mistake I did was that I forgot to use my custom built container in the docker-compose.yml. So everytime I started docker-compose run --rm server create_db and then docker-compose up -d I used the official redash/redash container and not my custom built. 
Because of that my custom Dockerfile did nothing and the official one was used. <img width="20" height="20" src="https://emoji.discourse-cdn.com/twitter/man_facepalming.png?v=10" title="man_facepalming" alt="man_facepalming" class="emoji"> 
For everyone else who struggles with the oracle …
  </blockquote>
</aside>

<p>After that, the Oracle is shown in the data sources, but the Mysql and Oracle throw the above error messages. If I ran this command ( <em>docker-compose build server</em> ), then the Mysql data source is working but the Oracle has disappeared. Could you please help me what is the mistake?</p>
          <p><a href="https://discuss.redash.io/t/unknown-error-occurred-while-performing-connection-test/9411/17">Read full topic</a></p>
        ]]></description>
        <link>https://discuss.redash.io/t/unknown-error-occurred-while-performing-connection-test/9411/17</link>
        <pubDate>Thu, 25 Nov 2021 09:32:38 +0000</pubDate>
        <guid isPermaLink="false">discuss.redash.io-post-9411-17</guid>
        <source url="https://discuss.redash.io/t/unknown-error-occurred-while-performing-connection-test/9411.rss">Unknown error occurred while performing connection test</source>
      </item>
      <item>
        <title>Unknown error occurred while performing connection test</title>
        <dc:creator><![CDATA[adam09066]]></dc:creator>
        <description><![CDATA[
            <p>Finally it’s working. I tried to install the Redash from the beginning.</p>
<p>I used the docker-compose down command, after that I followed the step by step instruction and it is working. I don’t know how because I did not changed anything.</p>
<p>Sorry for wasting your time and thank you for your help anyway.</p>
          <p><a href="https://discuss.redash.io/t/unknown-error-occurred-while-performing-connection-test/9411/16">Read full topic</a></p>
        ]]></description>
        <link>https://discuss.redash.io/t/unknown-error-occurred-while-performing-connection-test/9411/16</link>
        <pubDate>Tue, 09 Nov 2021 13:55:06 +0000</pubDate>
        <guid isPermaLink="false">discuss.redash.io-post-9411-16</guid>
        <source url="https://discuss.redash.io/t/unknown-error-occurred-while-performing-connection-test/9411.rss">Unknown error occurred while performing connection test</source>
      </item>
      <item>
        <title>Unknown error occurred while performing connection test</title>
        <dc:creator><![CDATA[adam09066]]></dc:creator>
        <description><![CDATA[
            <p>I did the testing for the first time and if I did everything correctly, then I received the same errors</p>
<p></p><div class="lightbox-wrapper"><a class="lightbox" href="https://global.discourse-cdn.com/standard17/uploads/redash1/original/2X/0/04a21d68a8bf3c18951fc96fda29bded642230e1.png" data-download-href="/uploads/short-url/EZeQhhbK6iTZCZM7LpjyWdjbfr.png?dl=1" title="image" rel="noopener nofollow ugc"><img src="https://global.discourse-cdn.com/standard17/uploads/redash1/optimized/2X/0/04a21d68a8bf3c18951fc96fda29bded642230e1_2_614x500.png" alt="image" data-base62-sha1="EZeQhhbK6iTZCZM7LpjyWdjbfr" width="614" height="500" srcset="https://global.discourse-cdn.com/standard17/uploads/redash1/optimized/2X/0/04a21d68a8bf3c18951fc96fda29bded642230e1_2_614x500.png, https://global.discourse-cdn.com/standard17/uploads/redash1/optimized/2X/0/04a21d68a8bf3c18951fc96fda29bded642230e1_2_921x750.png 1.5x, https://global.discourse-cdn.com/standard17/uploads/redash1/optimized/2X/0/04a21d68a8bf3c18951fc96fda29bded642230e1_2_1228x1000.png 2x" data-small-upload="https://global.discourse-cdn.com/standard17/uploads/redash1/optimized/2X/0/04a21d68a8bf3c18951fc96fda29bded642230e1_2_10x10.png"></a></div><p></p>
<p>Traceback (most recent call last):<br>
File “/usr/local/lib/python3.7/site-packages/flask/app.py”, line 2463, in <strong>call</strong><br>
return self.wsgi_app(environ, start_response)<br>
File “/usr/local/lib/python3.7/site-packages/werkzeug/middleware/proxy_fix.py”, line 232, in <strong>call</strong><br>
return self.app(environ, start_response)<br>
File “/usr/local/lib/python3.7/site-packages/flask/app.py”, line 2449, in wsgi_app<br>
response = self.handle_exception(e)<br>
File “/usr/local/lib/python3.7/site-packages/flask_restful/<strong>init</strong>.py”, line 269, in error_router<br>
return original_handler(e)<br>
File “/usr/local/lib/python3.7/site-packages/flask/app.py”, line 1866, in handle_exception<br>
reraise(exc_type, exc_value, tb)<br>
File “/usr/local/lib/python3.7/site-packages/flask/_compat.py”, line 38, in reraise<br>
raise value.with_traceback(tb)<br>
File “/usr/local/lib/python3.7/site-packages/flask/app.py”, line 2446, in wsgi_app<br>
response = self.full_dispatch_request()<br>
File “/usr/local/lib/python3.7/site-packages/flask/app.py”, line 1951, in full_dispatch_request<br>
rv = self.handle_user_exception(e)<br>
File “/usr/local/lib/python3.7/site-packages/flask_restful/<strong>init</strong>.py”, line 269, in error_router<br>
return original_handler(e)<br>
File “/usr/local/lib/python3.7/site-packages/flask/app.py”, line 1820, in handle_user_exception<br>
reraise(exc_type, exc_value, tb)<br>
File “/usr/local/lib/python3.7/site-packages/flask/_compat.py”, line 38, in reraise<br>
raise value.with_traceback(tb)<br>
File “/usr/local/lib/python3.7/site-packages/flask/app.py”, line 1949, in full_dispatch_request<br>
rv = self.dispatch_request()<br>
File “/usr/local/lib/python3.7/site-packages/flask/app.py”, line 1935, in dispatch_request<br>
return self.view_functions<a href="https://discuss.redash.io">rule.endpoint</a><br>
File “/usr/local/lib/python3.7/site-packages/flask_restful/<strong>init</strong>.py”, line 458, in wrapper<br>
resp = resource(*args, **kwargs)<br>
File “/usr/local/lib/python3.7/site-packages/flask_login/utils.py”, line 261, in decorated_view<br>
return func(*args, **kwargs)<br>
File “/usr/local/lib/python3.7/site-packages/flask/views.py”, line 89, in view<br>
return self.dispatch_request(*args, **kwargs)<br>
File “/app/redash/handlers/base.py”, line 33, in dispatch_request<br>
return super(BaseResource, self).dispatch_request(*args, **kwargs)<br>
File “/usr/local/lib/python3.7/site-packages/flask_restful/<strong>init</strong>.py”, line 573, in dispatch_request<br>
resp = meth(*args, **kwargs)<br>
File “/app/redash/permissions.py”, line 71, in decorated<br>
return fn(*args, **kwargs)<br>
File “/app/redash/handlers/data_sources.py”, line 263, in post<br>
job.refresh()<br>
File “/usr/local/lib/python3.7/site-packages/rq/job.py”, line 518, in refresh<br>
raise NoSuchJobError(‘No such job: {0}’.format(self.key))<br>
rq.exceptions.NoSuchJobError: No such job: b’rq:job:99ec58fe-97ff-4f47-a2b0-5f7c09205a6a’</p>
          <p><a href="https://discuss.redash.io/t/unknown-error-occurred-while-performing-connection-test/9411/15">Read full topic</a></p>
        ]]></description>
        <link>https://discuss.redash.io/t/unknown-error-occurred-while-performing-connection-test/9411/15</link>
        <pubDate>Tue, 09 Nov 2021 08:09:13 +0000</pubDate>
        <guid isPermaLink="false">discuss.redash.io-post-9411-15</guid>
        <source url="https://discuss.redash.io/t/unknown-error-occurred-while-performing-connection-test/9411.rss">Unknown error occurred while performing connection test</source>
      </item>
      <item>
        <title>Unknown error occurred while performing connection test</title>
        <dc:creator><![CDATA[jesse]]></dc:creator>
        <description><![CDATA[
            <p>Peculiar.</p>
<p>Are you comfortable using your browser’s network inspector? If so, what happens in the <em>Network</em> tab when you click the connection test button?</p>
<p>I’ll ask this question again:</p>
<blockquote>
<p>Also, despite the connection test: what happens if you try to run a query?</p>
</blockquote>
          <p><a href="https://discuss.redash.io/t/unknown-error-occurred-while-performing-connection-test/9411/14">Read full topic</a></p>
        ]]></description>
        <link>https://discuss.redash.io/t/unknown-error-occurred-while-performing-connection-test/9411/14</link>
        <pubDate>Mon, 08 Nov 2021 16:31:11 +0000</pubDate>
        <guid isPermaLink="false">discuss.redash.io-post-9411-14</guid>
        <source url="https://discuss.redash.io/t/unknown-error-occurred-while-performing-connection-test/9411.rss">Unknown error occurred while performing connection test</source>
      </item>
      <item>
        <title>Unknown error occurred while performing connection test</title>
        <dc:creator><![CDATA[adam09066]]></dc:creator>
        <description><![CDATA[
            <p>Yes it is running.</p>
<p></p><div class="lightbox-wrapper"><a class="lightbox" href="https://global.discourse-cdn.com/standard17/uploads/redash1/original/2X/2/2fbd9c0ce4ec2c36c03478a19ebe4b8d156d9973.png" data-download-href="/uploads/short-url/6OkG1fConNCO7imiTbAXUWHY8Cf.png?dl=1" title="image" rel="noopener nofollow ugc"><img src="https://global.discourse-cdn.com/standard17/uploads/redash1/original/2X/2/2fbd9c0ce4ec2c36c03478a19ebe4b8d156d9973.png" alt="image" data-base62-sha1="6OkG1fConNCO7imiTbAXUWHY8Cf" width="690" height="47" data-small-upload="https://global.discourse-cdn.com/standard17/uploads/redash1/optimized/2X/2/2fbd9c0ce4ec2c36c03478a19ebe4b8d156d9973_2_10x10.png"></a></div><p></p>
          <p><a href="https://discuss.redash.io/t/unknown-error-occurred-while-performing-connection-test/9411/13">Read full topic</a></p>
        ]]></description>
        <link>https://discuss.redash.io/t/unknown-error-occurred-while-performing-connection-test/9411/13</link>
        <pubDate>Mon, 08 Nov 2021 15:56:32 +0000</pubDate>
        <guid isPermaLink="false">discuss.redash.io-post-9411-13</guid>
        <source url="https://discuss.redash.io/t/unknown-error-occurred-while-performing-connection-test/9411.rss">Unknown error occurred while performing connection test</source>
      </item>
      <item>
        <title>Unknown error occurred while performing connection test</title>
        <dc:creator><![CDATA[jesse]]></dc:creator>
        <description><![CDATA[
            <p>Is your Redis running?</p>
          <p><a href="https://discuss.redash.io/t/unknown-error-occurred-while-performing-connection-test/9411/12">Read full topic</a></p>
        ]]></description>
        <link>https://discuss.redash.io/t/unknown-error-occurred-while-performing-connection-test/9411/12</link>
        <pubDate>Mon, 08 Nov 2021 15:27:06 +0000</pubDate>
        <guid isPermaLink="false">discuss.redash.io-post-9411-12</guid>
        <source url="https://discuss.redash.io/t/unknown-error-occurred-while-performing-connection-test/9411.rss">Unknown error occurred while performing connection test</source>
      </item>
      <item>
        <title>Unknown error occurred while performing connection test</title>
        <dc:creator><![CDATA[adam09066]]></dc:creator>
        <description><![CDATA[
            <p>I followed the below instruction step by step:</p><aside class="onebox allowlistedgeneric" data-onebox-src="https://redash.io/help/open-source/dev-guide/docker/">
  <header class="source">
      <img src="https://redash.io/assets/images/favicon.ico" class="site-icon" width="16" height="16">

      <a href="https://redash.io/help/open-source/dev-guide/docker/" target="_blank" rel="noopener nofollow ugc">redash.io</a>
  </header>

  <article class="onebox-body">
    <div class="aspect-image" style="--aspect-ratio:690/362;"><img src="https://redash.io/assets/images/social-facebook-1200x630.png" class="thumbnail" width="690" height="362"></div>

<h3><a href="https://redash.io/help/open-source/dev-guide/docker/" target="_blank" rel="noopener nofollow ugc">Docker Based Developer Installation Guide</a></h3>



  </article>

  <div class="onebox-metadata">
    
    
  </div>

  <div style="clear: both"></div>
</aside>

<p>I am not using the kubernetes.</p>
          <p><a href="https://discuss.redash.io/t/unknown-error-occurred-while-performing-connection-test/9411/11">Read full topic</a></p>
        ]]></description>
        <link>https://discuss.redash.io/t/unknown-error-occurred-while-performing-connection-test/9411/11</link>
        <pubDate>Mon, 08 Nov 2021 15:19:15 +0000</pubDate>
        <guid isPermaLink="false">discuss.redash.io-post-9411-11</guid>
        <source url="https://discuss.redash.io/t/unknown-error-occurred-while-performing-connection-test/9411.rss">Unknown error occurred while performing connection test</source>
      </item>
      <item>
        <title>Unknown error occurred while performing connection test</title>
        <dc:creator><![CDATA[jesse]]></dc:creator>
        <description><![CDATA[
            <p>How did you set up Redash? Are you using kubernetes?</p>
          <p><a href="https://discuss.redash.io/t/unknown-error-occurred-while-performing-connection-test/9411/10">Read full topic</a></p>
        ]]></description>
        <link>https://discuss.redash.io/t/unknown-error-occurred-while-performing-connection-test/9411/10</link>
        <pubDate>Mon, 08 Nov 2021 13:20:53 +0000</pubDate>
        <guid isPermaLink="false">discuss.redash.io-post-9411-10</guid>
        <source url="https://discuss.redash.io/t/unknown-error-occurred-while-performing-connection-test/9411.rss">Unknown error occurred while performing connection test</source>
      </item>
      <item>
        <title>Unknown error occurred while performing connection test</title>
        <dc:creator><![CDATA[adam09066]]></dc:creator>
        <description><![CDATA[
            <p>connection test (docker_log):<br>
[2021-11-08 09:37:24,046][PID:15][INFO][werkzeug] 10.2.2.140 - - [08/Nov/2021 09:37:24] “POST /api/data_sources/3/test HTTP/1.1” 500 -</p>
<p>When i run a query then the scheme is loading but then nothing happens.<br>
i get some errors in docker logs:</p>
<p>[2021-11-08 09:31:56,819][PID:15][INFO][werkzeug] 10.2.2.140 - - [08/Nov/2021 09:31:56] “GET /api/jobs/d9bcc939-faba-495b-a7ef-de16ba1aa54e HTTP/1.1” 500 -<br>
Traceback (most recent call last):<br>
File “/usr/local/lib/python3.7/site-packages/flask/app.py”, line 2463, in <strong>call</strong><br>
return self.wsgi_app(environ, start_response)<br>
File “/usr/local/lib/python3.7/site-packages/werkzeug/middleware/proxy_fix.py”, line 232, in <strong>call</strong><br>
return self.app(environ, start_response)<br>
File “/usr/local/lib/python3.7/site-packages/flask/app.py”, line 2449, in wsgi_app<br>
response = self.handle_exception(e)<br>
File “/usr/local/lib/python3.7/site-packages/flask_restful/<strong>init</strong>.py”, line 269, in error_router<br>
return original_handler(e)<br>
File “/usr/local/lib/python3.7/site-packages/flask/app.py”, line 1866, in handle_exception<br>
reraise(exc_type, exc_value, tb)<br>
File “/usr/local/lib/python3.7/site-packages/flask/_compat.py”, line 38, in reraise<br>
raise value.with_traceback(tb)<br>
File “/usr/local/lib/python3.7/site-packages/flask/app.py”, line 2446, in wsgi_app<br>
response = self.full_dispatch_request()<br>
File “/usr/local/lib/python3.7/site-packages/flask/app.py”, line 1951, in full_dispatch_request<br>
rv = self.handle_user_exception(e)<br>
File “/usr/local/lib/python3.7/site-packages/flask_restful/<strong>init</strong>.py”, line 269, in error_router<br>
return original_handler(e)<br>
File “/usr/local/lib/python3.7/site-packages/flask/app.py”, line 1820, in handle_user_exception<br>
reraise(exc_type, exc_value, tb)<br>
File “/usr/local/lib/python3.7/site-packages/flask/_compat.py”, line 38, in reraise<br>
raise value.with_traceback(tb)<br>
File “/usr/local/lib/python3.7/site-packages/flask/app.py”, line 1949, in full_dispatch_request<br>
rv = self.dispatch_request()<br>
File “/usr/local/lib/python3.7/site-packages/flask/app.py”, line 1935, in dispatch_request<br>
return self.view_functions<a href="https://discuss.redash.io">rule.endpoint</a><br>
File “/usr/local/lib/python3.7/site-packages/flask_restful/<strong>init</strong>.py”, line 458, in wrapper<br>
resp = resource(*args, **kwargs)<br>
File “/usr/local/lib/python3.7/site-packages/flask_login/utils.py”, line 261, in decorated_view<br>
return func(*args, **kwargs)<br>
File “/usr/local/lib/python3.7/site-packages/flask/views.py”, line 89, in view<br>
return self.dispatch_request(*args, **kwargs)<br>
File “/app/redash/handlers/base.py”, line 33, in dispatch_request<br>
return super(BaseResource, self).dispatch_request(*args, **kwargs)<br>
File “/usr/local/lib/python3.7/site-packages/flask_restful/<strong>init</strong>.py”, line 573, in dispatch_request<br>
resp = meth(*args, **kwargs)<br>
File “/app/redash/handlers/query_results.py”, line 462, in get<br>
job = Job.fetch(job_id)<br>
File “/usr/local/lib/python3.7/site-packages/rq/job.py”, line 299, in fetch<br>
job.refresh()<br>
File “/usr/local/lib/python3.7/site-packages/rq/job.py”, line 518, in refresh<br>
raise NoSuchJobError(‘No such job: {0}’.format(self.key))<br>
rq.exceptions.NoSuchJobError: No such job: b’rq:job:d9bcc939-faba-495b-a7ef-de16ba1aa54e’</p>
          <p><a href="https://discuss.redash.io/t/unknown-error-occurred-while-performing-connection-test/9411/9">Read full topic</a></p>
        ]]></description>
        <link>https://discuss.redash.io/t/unknown-error-occurred-while-performing-connection-test/9411/9</link>
        <pubDate>Mon, 08 Nov 2021 09:52:03 +0000</pubDate>
        <guid isPermaLink="false">discuss.redash.io-post-9411-9</guid>
        <source url="https://discuss.redash.io/t/unknown-error-occurred-while-performing-connection-test/9411.rss">Unknown error occurred while performing connection test</source>
      </item>
      <item>
        <title>Unknown error occurred while performing connection test</title>
        <dc:creator><![CDATA[jesse]]></dc:creator>
        <description><![CDATA[
            <p>Do you see anything in your docker logs when you attempt the connection test?</p>
<p>Also, despite the connection test: what happens if you try to run a query?</p>
          <p><a href="https://discuss.redash.io/t/unknown-error-occurred-while-performing-connection-test/9411/8">Read full topic</a></p>
        ]]></description>
        <link>https://discuss.redash.io/t/unknown-error-occurred-while-performing-connection-test/9411/8</link>
        <pubDate>Fri, 05 Nov 2021 15:37:27 +0000</pubDate>
        <guid isPermaLink="false">discuss.redash.io-post-9411-8</guid>
        <source url="https://discuss.redash.io/t/unknown-error-occurred-while-performing-connection-test/9411.rss">Unknown error occurred while performing connection test</source>
      </item>
      <item>
        <title>Unknown error occurred while performing connection test</title>
        <dc:creator><![CDATA[adam09066]]></dc:creator>
        <description><![CDATA[
            <p>I tried to use the below 2 data sources:<br>
<img src="https://global.discourse-cdn.com/standard17/uploads/redash1/original/2X/9/93f65adb964637985996a0c6233b81c147dd5697.png" alt="image" data-base62-sha1="l6W04jG1cbm5LphzPka8KCfJyAf" width="490" height="278"></p>
          <p><a href="https://discuss.redash.io/t/unknown-error-occurred-while-performing-connection-test/9411/7">Read full topic</a></p>
        ]]></description>
        <link>https://discuss.redash.io/t/unknown-error-occurred-while-performing-connection-test/9411/7</link>
        <pubDate>Fri, 05 Nov 2021 15:16:19 +0000</pubDate>
        <guid isPermaLink="false">discuss.redash.io-post-9411-7</guid>
        <source url="https://discuss.redash.io/t/unknown-error-occurred-while-performing-connection-test/9411.rss">Unknown error occurred while performing connection test</source>
      </item>
      <item>
        <title>Unknown error occurred while performing connection test</title>
        <dc:creator><![CDATA[jesse]]></dc:creator>
        <description><![CDATA[
            <p>Which data source type did you use?</p>
          <p><a href="https://discuss.redash.io/t/unknown-error-occurred-while-performing-connection-test/9411/6">Read full topic</a></p>
        ]]></description>
        <link>https://discuss.redash.io/t/unknown-error-occurred-while-performing-connection-test/9411/6</link>
        <pubDate>Fri, 05 Nov 2021 15:03:54 +0000</pubDate>
        <guid isPermaLink="false">discuss.redash.io-post-9411-6</guid>
        <source url="https://discuss.redash.io/t/unknown-error-occurred-while-performing-connection-test/9411.rss">Unknown error occurred while performing connection test</source>
      </item>
      <item>
        <title>Unknown error occurred while performing connection test</title>
        <dc:creator><![CDATA[adam09066]]></dc:creator>
        <description><![CDATA[
            <p>I set the mentioned properties and I’m not using SSL. The MySQL Database is in the AWS cloud.</p>
          <p><a href="https://discuss.redash.io/t/unknown-error-occurred-while-performing-connection-test/9411/5">Read full topic</a></p>
        ]]></description>
        <link>https://discuss.redash.io/t/unknown-error-occurred-while-performing-connection-test/9411/5</link>
        <pubDate>Fri, 05 Nov 2021 14:56:10 +0000</pubDate>
        <guid isPermaLink="false">discuss.redash.io-post-9411-5</guid>
        <source url="https://discuss.redash.io/t/unknown-error-occurred-while-performing-connection-test/9411.rss">Unknown error occurred while performing connection test</source>
      </item>
      <item>
        <title>Unknown error occurred while performing connection test</title>
        <dc:creator><![CDATA[jesse]]></dc:creator>
        <description><![CDATA[
            <p>What can you tell us about your DB Configuration? Did you explicitly set the host, port, user, pass, and db name? Are you using SSL? Is this a stock MySQL Database? Is it housed on-premise or through a cloud?</p>
          <p><a href="https://discuss.redash.io/t/unknown-error-occurred-while-performing-connection-test/9411/4">Read full topic</a></p>
        ]]></description>
        <link>https://discuss.redash.io/t/unknown-error-occurred-while-performing-connection-test/9411/4</link>
        <pubDate>Fri, 05 Nov 2021 13:52:07 +0000</pubDate>
        <guid isPermaLink="false">discuss.redash.io-post-9411-4</guid>
        <source url="https://discuss.redash.io/t/unknown-error-occurred-while-performing-connection-test/9411.rss">Unknown error occurred while performing connection test</source>
      </item>
      <item>
        <title>Unknown error occurred while performing connection test</title>
        <dc:creator><![CDATA[adam09066]]></dc:creator>
        <description><![CDATA[
            <p>Yes, i can ping to DB from the Redash container.</p>
          <p><a href="https://discuss.redash.io/t/unknown-error-occurred-while-performing-connection-test/9411/3">Read full topic</a></p>
        ]]></description>
        <link>https://discuss.redash.io/t/unknown-error-occurred-while-performing-connection-test/9411/3</link>
        <pubDate>Fri, 05 Nov 2021 13:39:04 +0000</pubDate>
        <guid isPermaLink="false">discuss.redash.io-post-9411-3</guid>
        <source url="https://discuss.redash.io/t/unknown-error-occurred-while-performing-connection-test/9411.rss">Unknown error occurred while performing connection test</source>
      </item>
      <item>
        <title>Unknown error occurred while performing connection test</title>
        <dc:creator><![CDATA[jesse]]></dc:creator>
        <description><![CDATA[
            <p>That error message isn’t very helpful <img src="https://emoji.discourse-cdn.com/twitter/confused.png?v=10" title=":confused:" class="emoji" alt=":confused:"></p>
<aside class="quote no-group" data-username="adam09066" data-post="1" data-topic="9411">
<div class="title">
<div class="quote-controls"></div>
<img alt="" width="20" height="20" src="https://sjc6.discourse-cdn.com/standard17/user_avatar/discuss.redash.io/adam09066/40/3456_2.png" class="avatar"> adam09066:</div>
<blockquote>
<p>I can ping to Mysql DB from my terminal</p>
</blockquote>
</aside>
<p>Can you ping it from within the Redash container though?</p>
          <p><a href="https://discuss.redash.io/t/unknown-error-occurred-while-performing-connection-test/9411/2">Read full topic</a></p>
        ]]></description>
        <link>https://discuss.redash.io/t/unknown-error-occurred-while-performing-connection-test/9411/2</link>
        <pubDate>Fri, 05 Nov 2021 13:34:08 +0000</pubDate>
        <guid isPermaLink="false">discuss.redash.io-post-9411-2</guid>
        <source url="https://discuss.redash.io/t/unknown-error-occurred-while-performing-connection-test/9411.rss">Unknown error occurred while performing connection test</source>
      </item>
      <item>
        <title>Unknown error occurred while performing connection test</title>
        <dc:creator><![CDATA[adam09066]]></dc:creator>
        <description><![CDATA[
            <p>Hi Team,</p>
<p>I try to save the details of the DB connection properties and click on Test Connection, then I get error: Unknown error occurred while performing connection test. Please try again later"<br>
I can ping to Mysql DB from my terminal and the DB connection properties are correct.</p>
<p>Could somebody please help me what is causing the problem?</p>
<p>Thanks &amp; Regards,<br>
Adam</p>
          <p><a href="https://discuss.redash.io/t/unknown-error-occurred-while-performing-connection-test/9411/1">Read full topic</a></p>
        ]]></description>
        <link>https://discuss.redash.io/t/unknown-error-occurred-while-performing-connection-test/9411/1</link>
        <pubDate>Fri, 05 Nov 2021 08:02:01 +0000</pubDate>
        <guid isPermaLink="false">discuss.redash.io-post-9411-1</guid>
        <source url="https://discuss.redash.io/t/unknown-error-occurred-while-performing-connection-test/9411.rss">Unknown error occurred while performing connection test</source>
      </item>
  </channel>
</rss>
